Workbook

Sheet Experimental_summary
A1: Geometry of Gravimetric Absorption Auboidal Specimens
A2: Mix ID | B2: Type | C2: Height 1 (mm) | D2: Height 2(mm) | E2: Width 1(mm) | F2: Width 2(mm) | G2: Thickness 1 (mm) | H2: Thickness 2 (mm) | I2: Dry Mass (g) | J2: Avg Height (cm) | K2: Avg Width (cm) | L2: Avg Thickness (cm) | M2: Absorption Area (cm2) | N2: Remarks
A3: HS-1 | B3: 0.7-1d | C3: 20.8 | D3: 21.4 | E3: 23.6 | F3: 23.9 | G3: 23.8 | H3: 23.9 | I3: 14.92 | J3: 2.11 | K3: 2.375 | L3: 2.385 | M3: 5.664 | N3: ***
A4: HS-2 | B4: 0.7-1d | C4: 20.8 | D4: 20.9 | E4: 24.4 | F4: 24.6 | G4: 24.3 | H4: 24.4 | I4: 15 | J4: 2.085 | K4: 2.45 | L4: 2.435 | M4: 5.966
A5: HS-3 | B5: 0.7-1d | C5: 20.5 | D5: 20.7 | E5: 24 | F5: 24.1 | G5: 23.7 | H5: 23.8 | I5: 14.54 | J5: 2.06 | K5: 2.405 | L5: 2.375 | M5: 5.712
A6: MS-1 | B6: 0.7-7d | C6: 19.8 | D6: 19.9 | E6: 23.7 | F6: 23.8 | G6: 24.2 | H6: 24 | I6: 14.34 | J6: 1.985 | K6: 2.375 | L6: 2.41 | M6: 5.724 | N6: ***
A7: MS-2 | B7: 0.7-7d | C7: 19.4 | D7: 19.5 | E7: 24.2 | F7: 24.6 | G7: 23.7 | H7: 23.9 | I7: 14.47 | J7: 1.945 | K7: 2.44 | L7: 2.38 | M7: 5.807
A8: MS-3 | B8: 0.7-7d | C8: 20.3 | D8: 20.6 | E8: 24.4 | F8: 24.5 | G8: 24.6 | H8: 24.4 | I8: 15.11 | J8: 2.045 | K8: 2.445 | L8: 2.45 | M8: 5.99
A9: LS-1 | B9: 0.45-1d | C9: 21.7 | D9: 21.2 | E9: 24.2 | F9: 24 | G9: 24.1 | H9: 24.3 | I9: 19.28 | J9: 2.145 | K9: 2.41 | L9: 2.42 | M9: 5.832
A10: LS-2 | B10: 0.45-1d | C10: 21.2 | D10: 21.6 | E10: 24.5 | F10: 24.3 | G10: 24.4 | H10: 24.8 | I10: 19.85 | J10: 2.14 | K10: 2.44 | L10: 2.46 | M10: 6.002 | N10: ***
A11: LS-3 | B11: 0.45-1d | C11: 21.8 | D11: 21.9 | E11: 24.7 | F11: 25 | G11: 24.2 | H11: 24.7 | I11: 20.32 | J11: 2.185 | K11: 2.485 | L11: 2.445 | M11: 6.076
A12: *** samples used for experimental validation of learned diffusivity functions
A16: Time | B16: Cumulative Absorption (Volumetric Absorbed Water per unit Absorption Area) (cm)
A17: (min) | B17: HS-1 | C17: HS-2 | D17: HS-3 | E17: MS-1 | F17: MS-2 | G17: MS-3 | H17: LS-1 | I17: LS-2 | J17: LS-3
A18: 0 | B18: 0 | C18: 0 | D18: 0 | E18: 0 | F18: 0 | G18: 0 | H18: 0 | I18: 0 | J18: 0
A19: 5 | B19: 0.516 | C19: 0.5 | D19: 0.516 | E19: 0.19 | F19: 0.319 | G19: 0.179 | H19: 0.175 | I19: 0.17 | J19: 0.183
A20: 10 | B20: 0.651 | C20: 0.627 | D20: 0.644 | E20: 0.246 | F20: 0.393 | G20: 0.229 | H20: 0.223 | I20: 0.218 | J20: 0.232
A21: 15 | B21: 0.771 | C21: 0.739 | D21: 0.76 | E21: 0.301 | F21: 0.47 | G21: 0.279 | H21: 0.261 | I21: 0.253 | J21: 0.27
A22: 30 | B22: 0.89 | C22: 0.858 | D22: 0.872 | E22: 0.416 | F22: 0.634 | G22: 0.404 | H22: 0.327 | I22: 0.322 | J22: 0.342
A23: 45 | B23: 0.89 | C23: 0.858 | D23: 0.872 | E23: 0.507 | F23: 0.753 | G23: 0.497 | H23: 0.379 | I23: 0.372 | J23: 0.393
A24: 60 | B24: 0.893 | C24: 0.862 | D24: 0.874 | E24: 0.575 | F24: 0.835 | G24: 0.573 | H24: 0.415 | I24: 0.408 | J24: 0.433
A25: 90 | B25: 0.893 | C25: 0.863 | D25: 0.875 | E25: 0.699 | F25: 0.858 | G25: 0.701 | H25: 0.477 | I25: 0.466 | J25: 0.49
A26: 120 | B26: 0.893 | C26: 0.865 | D26: 0.875 | E26: 0.793 | F26: 0.859 | G26: 0.8 | H26: 0.521 | I26: 0.51 | J26: 0.535
A27: 180 | B27: 0.897 | C27: 0.865 | D27: 0.877 | E27: 0.893 | F27: 0.859 | G27: 0.9 | H27: 0.59 | I27: 0.576 | J27: 0.601
A28: 240 | B28: 0.9 | C28: 0.87 | D28: 0.879 | E28: 0.902 | F28: 0.863 | G28: 0.905 | H28: 0.638 | I28: 0.625 | J28: 0.64
A29: 300 | B29: 0.897 | C29: 0.872 | D29: 0.882 | E29: 0.903 | F29: 0.863 | G29: 0.91 | H29: 0.655 | I29: 0.643 | J29: 0.653
... A32: 10080 | B32: 0.964 | C32: 0.932 | D32: 0.926 | E32: 0.961 | F32: 0.925 | G32: 0.965 | H32: 0.715 | I32: 0.711 | J32: 0.713
A33: HS-1, MS-1, and LS-2 (highlighted in grey) were used for experimental validation of the learned diffusivity model
A36: Time (min) | B36: Absorbed Water Content (g/cm3)
B38: HS-1 | C38: HS-2 | D38: HS-3 | E38: MS-1 | F38: MS-2 | G38: MS-3 | H38: LS-1 | I38: LS-2 | J38: LS-3
A39: 0 | B39: 0 | C39: 0 | D39: 0 | E39: 0 | F39: 0 | G39: 0 | H39: 0 | I39: 0 | J39: 0
A40: 420 | B40: 0.429 | C40: 0.419 | D40: 0.431 | E40: 0.457 | F40: 0.446 | G40: 0.447 | H40: 0.309 | I40: 0.306 | J40: 0.301
A41: 10080 | B41: 0.457 | C41: 0.447 | D41: 0.45 | E41: 0.484 | F41: 0.475 | G41: 0.472 | H41: 0.333 | I41: 0.332 | J41: 0.326
A42: Avg. 420 min (7hr) | B42: =AVERAGE(B40:D40) -> 0.42633333 | E42: =AVERAGE(E40:G40) -> 0.45 | H42: =AVERAGE(H40:J40) -> 0.30533333
A43: Avg. 10080 min (7d) | B43: =AVERAGE(B41:D41) -> 0.45133333 | E43: =AVERAGE(E41:G41) -> 0.477 | H43: =AVERAGE(H41:J41) -> 0.33033333
A47: Extracted for Plotting
A49: Gravimetric 7 hr (avg) | B49: X-ray | C49: Remarks
A50: =B42 -> 0.42633333 | B50: =HS_Xray_Quantified_Lin_attn!B30 -> 0.52596153 | C50: HS
A51: =E42 -> 0.45 | B51: =MS_Xray_Quantified_Lin_attn!B25 -> 0.55026559 | C51: MS
A52: =H42 -> 0.30533333 | B52: =LS_Xray_Quantified_Lin_attn!B31 -> 0.39684243 | C52: LS
...

Sheet Gravimetric_test_raw_data
D1: Measured Mass of the Specimen (g)
A2: Mix ID | B2: Start Date | C2: Start Time | D2: 0 | E2: 5 | F2: 10 | G2: 15 | H2: 30 | I2: 45 | J2: 60 | K2: 90 | L2: 120 | M2: 180 | N2: 240 | O2: 300 | P2: 360 | Q2: 420 | R2: 7 Days
A3: 0.7-1d-1 | B3: 45651 | C3: 0.54166667 | D3: 14.92 | E3: 17.84 | F3: 18.61 | G3: 19.29 | H3: 19.96 | I3: 19.96 | J3: 19.98 | K3: 19.98 | L3: 19.98 | M3: 20 | N3: 20.02 | O3: 20 | P3: 20.04 | Q3: 20.05 | R3: 20.38
A4: 0.7-1d-2 | B4: 45651 | C4: 0.54166667 | D4: 15 | E4: 17.98 | F4: 18.74 | G4: 19.41 | H4: 20.12 | I4: 20.12 | J4: 20.14 | K4: 20.15 | L4: 20.16 | M4: 20.16 | N4: 20.19 | O4: 20.2 | P4: 20.21 | Q4: 20.21 | R4: 20.56
A5: 0.7-1d-3 | B5: 45651 | C5: 0.54166667 | D5: 14.54 | E5: 17.49 | F5: 18.22 | G5: 18.88 | H5: 19.52 | I5: 19.52 | J5: 19.53 | K5: 19.54 | L5: 19.54 | M5: 19.55 | N5: 19.56 | O5: 19.58 | P5: 19.6 | Q5: 19.61 | R5: 19.83
A6: 0.7-7d-1 | B6: 45651 | C6: 0.54166667 | D6: 14.34 | E6: 15.43 | F6: 15.75 | G6: 16.06 | H6: 16.72 | I6: 17.24 | J6: 17.63 | K6: 18.34 | L6: 18.88 | M6: 19.45 | N6: 19.5 | O6: 19.51 | P6: 19.52 | Q6: 19.53 | R6: 19.84
A7: 0.7-7d-2 | B7: 45651 | C7: 0.54166667 | D7: 14.47 | E7: 16.32 | F7: 16.75 | G7: 17.2 | H7: 18.15 | I7: 18.84 | J7: 19.32 | K7: 19.45 | L7: 19.46 | M7: 19.46 | N7: 19.48 | O7: 19.48 | P7: 19.5 | Q7: 19.51 | R7: 19.84
A8: 0.7-7d-3 | B8: 45651 | C8: 0.54166667 | D8: 15.11 | E8: 16.18 | F8: 16.48 | G8: 16.78 | H8: 17.53 | I8: 18.09 | J8: 18.54 | K8: 19.31 | L8: 19.9 | M8: 20.5 | N8: 20.53 | O8: 20.56 | P8: 20.57 | Q8: 20.58 | R8: 20.89
A9: 0.45-1d-1 | B9: 45651 | C9: 0.54166667 | D9: 19.28 | E9: 20.3 | F9: 20.58 | G9: 20.8 | H9: 21.19 | I9: 21.49 | J9: 21.7 | K9: 22.06 | L9: 22.32 | M9: 22.72 | N9: 23 | O9: 23.1 | P9: 23.14 | Q9: 23.15 | R9: 23.45
A10: 0.45-1d-2 | B10: 45651 | C10: 0.54166667 | D10: 19.85 | E10: 20.87 | F10: 21.16 | G10: 21.37 | H10: 21.78 | I10: 22.08 | J10: 22.3 | K10: 22.65 | L10: 22.91 | M10: 23.31 | N10: 23.6 | O10: 23.71 | P10: 23.76 | Q10: 23.78 | R10: 24.12
A11: 0.45-1d-3 | B11: 45651 | C11: 0.54166667 | D11: 20.32 | E11: 21.43 | F11: 21.73 | G11: 21.96 | H11: 22.4 | I11: 22.71 | J11: 22.95 | K11: 23.3 | L11: 23.57 | M11: 23.97 | N11: 24.21 | O11: 24.29 | P11: 24.3 | Q11: 24.32 | R11: 24.65
D14: Measured Mass of the Specimen (gm) or Volmetric Absorption Equivalent (cm3) - assuming water 1g/cm3
A15: Mix ID | B15: Base Area (cm2) | D15: 0 | E15: 5 | F15: 10 | G15: 15 | H15: 30 | I15: 45 | J15: 60 | K15: 90 | L15: 120 | M15: 180 | N15: 240 | O15: 300 | P15: 360 | Q15: 420 | R15: 7 Days
A16: 0.7-1d-1 | B16: =AVERAGE(Experimental_summary!E3:F3) * AVERAGE(Experimental_summary!G3:H3)/100 -> 5.664375 | D16: =D3-$D3 -> 0 | E16: =E3-$D3 -> 2.92 | F16: =F3-$D3 -> 3.69 | G16: =G3-$D3 -> 4.37 | H16: =H3-$D3 -> 5.04 | I16: =I3-$D3 -> 5.04 | J16: =J3-$D3 -> 5.06 | K16: =K3-$D3 -> 5.06 | ... R16: =R3-$D3 -> 5.46
A17: 0.7-1d-2 | B17: =AVERAGE(Experimental_summary!E4:F4) * AVERAGE(Experimental_summary!G4:H4)/100 -> 5.96575 | D17: =D4-$D4 -> 0 | E17: =E4-$D4 -> 2.98 | F17: =F4-$D4 -> 3.74 | G17: =G4-$D4 -> 4.41 | H17: =H4-$D4 -> 5.12 | I17: =I4-$D4 -> 5.12 | J17: =J4-$D4 -> 5.14 | K17: =K4-$D4 -> 5.15 | ... R17: =R4-$D4 -> 5.56
A18: 0.7-1d-3 | B18: =AVERAGE(Experimental_summary!E5:F5) * AVERAGE(Experimental_summary!G5:H5)/100 -> 5.711875 | D18: =D5-$D5 -> 0 | E18: =E5-$D5 -> 2.95 | F18: =F5-$D5 -> 3.68 | G18: =G5-$D5 -> 4.34 | H18: =H5-$D5 -> 4.98 | I18: =I5-$D5 -> 4.98 | J18: =J5-$D5 -> 4.99 | K18: =K5-$D5 -> 5 | ... R18: =R5-$D5 -> 5.29
A19: 0.7-7d-1 | B19: =AVERAGE(Experimental_summary!E6:F6) * AVERAGE(Experimental_summary!G6:H6)/100 -> 5.72375 | D19: =D6-$D6 -> 0 | E19: =E6-$D6 -> 1.09 | F19: =F6-$D6 -> 1.41 | G19: =G6-$D6 -> 1.72 | H19: =H6-$D6 -> 2.38 | I19: =I6-$D6 -> 2.9 | J19: =J6-$D6 -> 3.29 | K19: =K6-$D6 -> 4 | ... R19: =R6-$D6 -> 5.5
A20: 0.7-7d-2 | B20: =AVERAGE(Experimental_summary!E7:F7) * AVERAGE(Experimental_summary!G7:H7)/100 -> 5.8072 | D20: =D7-$D7 -> 0 | E20: =E7-$D7 -> 1.85 | F20: =F7-$D7 -> 2.28 | G20: =G7-$D7 -> 2.73 | H20: =H7-$D7 -> 3.68 | I20: =I7-$D7 -> 4.37 | J20: =J7-$D7 -> 4.85 | K20: =K7-$D7 -> 4.98 | ... R20: =R7-$D7 -> 5.37
A21: 0.7-7d-3 | B21: =AVERAGE(Experimental_summary!E8:F8) * AVERAGE(Experimental_summary!G8:H8)/100 -> 5.99025 | D21: =D8-$D8 -> 0 | E21: =E8-$D8 -> 1.07 | F21: =F8-$D8 -> 1.37 | G21: =G8-$D8 -> 1.67 | H21: =H8-$D8 -> 2.42 | I21: =I8-$D8 -> 2.98 | J21: =J8-$D8 -> 3.43 | K21: =K8-$D8 -> 4.2 | ... R21: =R8-$D8 -> 5.78
A22: 0.45-1d-1 | B22: =AVERAGE(Experimental_summary!E9:F9) * AVERAGE(Experimental_summary!G9:H9)/100 -> 5.8322 | D22: =D9-$D9 -> 0 | E22: =E9-$D9 -> 1.02 | F22: =F9-$D9 -> 1.3 | G22: =G9-$D9 -> 1.52 | H22: =H9-$D9 -> 1.91 | I22: =I9-$D9 -> 2.21 | J22: =J9-$D9 -> 2.42 | K22: =K9-$D9 -> 2.78 | ... R22: =R9-$D9 -> 4.17
A23: 0.45-1d-2 | B23: =AVERAGE(Experimental_summary!E10:F10) * AVERAGE(Experimental_summary!G10:H10)/100 -> 6.0024 | D23: =D10-$D10 -> 0 | E23: =E10-$D10 -> 1.02 | F23: =F10-$D10 -> 1.31 | G23: =G10-$D10 -> 1.52 | H23: =H10-$D10 -> 1.93 | I23: =I10-$D10 -> 2.23 | J23: =J10-$D10 -> 2.45 | K23: =K10-$D10 -> 2.8 | ... R23: =R10-$D10 -> 4.27
A24: 0.45-1d-3 | B24: =AVERAGE(Experimental_summary!E11:F11) * AVERAGE(Experimental_summary!G11:H11)/100 -> 6.075825 | D24: =D11-$D11 -> 0 | E24: =E11-$D11 -> 1.11 | F24: =F11-$D11 -> 1.41 | G24: =G11-$D11 -> 1.64 | H24: =H11-$D11 -> 2.08 | I24: =I11-$D11 -> 2.39 | J24: =J11-$D11 -> 2.63 | K24: =K11-$D11 -> 2.98 | ... R24: =R11-$D11 -> 4.33
D26: Absorbed Mass per unit absorption area (gm/cm2) | or Equivalently Cumulative Absorption (cm) in water column height
A27: Mix ID | D27: 0 | E27: 5 | F27: 10 | G27: 15 | H27: 30 | I27: 45 | J27: 60 | K27: 90 | L27: 120 | M27: 180 | N27: 240 | O27: 300 | P27: 360 | Q27: 420 | R27: 7 Days
A28: 0.7-1d-1 | D28: =D16/$B16 -> 0 | E28: =E16/$B16 -> 0.51550259 | F28: =F16/$B16 -> 0.65143992 | G28: =G16/$B16 -> 0.77148847 | H28: =H16/$B16 -> 0.8897716 | I28: =I16/$B16 -> 0.8897716 | J28: =J16/$B16 -> 0.89330244 | K28: =K16/$B16 -> 0.89330244 | ... R28: =R16/$B16 -> 0.96391923
A29: 0.7-1d-2 | D29: =D17/$B17 -> 0 | E29: =E17/$B17 -> 0.49951808 | F29: =F17/$B17 -> 0.62691196 | G29: =G17/$B17 -> 0.73921971 | H29: =H17/$B17 -> 0.85823241 | I29: =I17/$B17 -> 0.85823241 | J29: =J17/$B17 -> 0.86158488 | K29: =K17/$B17 -> 0.86326112 | ... R29: =R17/$B17 -> 0.93198676
A30: 0.7-1d-3 | D30: =D18/$B18 -> 0 | E30: =E18/$B18 -> 0.51646788 | F30: =F18/$B18 -> 0.6442718 | G30: =G18/$B18 -> 0.75982055 | H30: =H18/$B18 -> 0.87186782 | I30: =I18/$B18 -> 0.87186782 | J30: =J18/$B18 -> 0.87361856 | K30: =K18/$B18 -> 0.8753693 | ... R30: =R18/$B18 -> 0.92614072
A31: 0.7-7d-1 | D31: =D19/$B19 -> 0 | E31: =E19/$B19 -> 0.19043459 | F31: =F19/$B19 -> 0.246342 | G31: =G19/$B19 -> 0.30050229 | H31: =H19/$B19 -> 0.41581131 | I31: =I19/$B19 -> 0.50666084 | J31: =J19/$B19 -> 0.57479799 | K31: =K19/$B19 -> 0.69884254 | ... R31: =R19/$B19 -> 0.9609085
A32: 0.7-7d-2 | D32: =D20/$B20 -> 0 | E32: =E20/$B20 -> 0.31857005 | F32: =F20/$B20 -> 0.39261606 | G32: =G20/$B20 -> 0.47010608 | H32: =H20/$B20 -> 0.6336961 | I32: =I20/$B20 -> 0.75251412 | J32: =J20/$B20 -> 0.83517013 | K32: =K20/$B20 -> 0.85755614 | ... R32: =R20/$B20 -> 0.92471415
A33: 0.7-7d-3 | D33: =D21/$B21 -> 0 | E33: =E21/$B21 -> 0.1786236 | F33: =F21/$B21 -> 0.22870498 | G33: =G21/$B21 -> 0.27878636 | H33: =H21/$B21 -> 0.40398982 | I33: =I21/$B21 -> 0.49747506 | J33: =J21/$B21 -> 0.57259714 | K33: =K21/$B21 -> 0.70113935 | ... R33: =R21/$B21 -> 0.9649013
A34: 0.45-1d-1 | D34: =D22/$B22 -> 0 | E34: =E22/$B22 -> 0.17489112 | F34: =F22/$B22 -> 0.22290045 | G34: =G22/$B22 -> 0.26062206 | H34: =H22/$B22 -> 0.3274922 | I34: =I22/$B22 -> 0.37893076 | J34: =J22/$B22 -> 0.41493776 | K34: =K22/$B22 -> 0.47666404 | ... R34: =R22/$B22 -> 0.71499606
A35: 0.45-1d-2 | D35: =D23/$B23 -> 0 | E35: =E23/$B23 -> 0.16993203 | F35: =F23/$B23 -> 0.21824603 | G35: =G23/$B23 -> 0.25323204 | H35: =H23/$B23 -> 0.32153805 | I35: =I23/$B23 -> 0.37151806 | J35: =J23/$B23 -> 0.40817007 | K35: =K23/$B23 -> 0.46648007 | ... R35: =R23/$B23 -> 0.71138211
A36: 0.45-1d-3 | D36: =D24/$B24 -> 0 | E36: =E24/$B24 -> 0.18269124 | F36: =F24/$B24 -> 0.23206725 | G36: =G24/$B24 -> 0.26992219 | H36: =H24/$B24 -> 0.34234034 | I36: =I24/$B24 -> 0.39336222 | J36: =J24/$B24 -> 0.43286303 | K36: =K24/$B24 -> 0.49046837 | ... R36: =R24/$B24 -> 0.71266042
D39: Total Absorbed Water convent per unit bulk volume of specimen (g/cm3)
A40: Mix ID | B40: Avg. Height (cm) | D40: 0 | E40: 5 | F40: 10 | G40: 15 | H40: 30 | I40: 45 | J40: 60 | K40: 90 | L40: 120 | M40: 180 | N40: 240 | O40: 300 | P40: 360 | Q40: 420 | R40: 7 Days
A41: 0.7-1d-1 | B41: =Experimental_summary!J3 -> 2.11 | D41: =D28/$B41 -> 0 | E41: =E28/$B41 -> 0.24431403 | F41: =F28/$B41 -> 0.3087393 | G41: =G28/$B41 -> 0.36563435 | H41: =H28/$B41 -> 0.4216927 | I41: =I28/$B41 -> 0.4216927 | J41: =J28/$B41 -> 0.42336608 | K41: =K28/$B41 -> 0.42336608 | ... R41: =R28/$B41 -> 0.45683376
A42: 0.7-1d-2 | B42: =Experimental_summary!J4 -> 2.085 | D42: =D29/$B42 -> 0 | E42: =E29/$B42 -> 0.23957702 | F42: =F29/$B42 -> 0.3006772 | G42: =G29/$B42 -> 0.35454183 | H42: =H29/$B42 -> 0.41162226 | I42: =I29/$B42 -> 0.41162226 | J42: =J29/$B42 -> 0.41323016 | K42: =K29/$B42 -> 0.41403411 | ... R42: =R29/$B42 -> 0.44699605
A43: 0.7-1d-3 | B43: =Experimental_summary!J5 -> 2.06 | D43: =D30/$B43 -> 0 | E43: =E30/$B43 -> 0.25071257 | F43: =F30/$B43 -> 0.3127533 | G43: =G30/$B43 -> 0.36884493 | H43: =H30/$B43 -> 0.42323681 | I43: =I30/$B43 -> 0.42323681 | J43: =J30/$B43 -> 0.42408668 | K43: =K30/$B43 -> 0.42493655 | ... R43: =R30/$B43 -> 0.44958287
A44: 0.7-7d-1 | B44: =Experimental_summary!J6 -> 1.985 | D44: =D31/$B44 -> 0 | E44: =E31/$B44 -> 0.095936823 | F44: =F31/$B44 -> 0.12410176 | G44: =G31/$B44 -> 0.15138655 | H44: =H31/$B44 -> 0.20947673 | I44: =I31/$B44 -> 0.25524476 | J44: =J31/$B44 -> 0.28957078 | K44: =K31/$B44 -> 0.35206173 | ... R44: =R31/$B44 -> 0.48408488
A45: 0.7-7d-2 | B45: =Experimental_summary!J7 -> 1.945 | D45: =D32/$B45 -> 0 | E45: =E32/$B45 -> 0.16378923 | F45: =F32/$B45 -> 0.20185916 | G45: =G32/$B45 -> 0.24169978 | H45: =H32/$B45 -> 0.32580776 | I45: =I32/$B45 -> 0.38689672 | J45: =J32/$B45 -> 0.42939338 | K45: =K32/$B45 -> 0.4409029 | ... R45: =R32/$B45 -> 0.47543144
...

Sheet HS_Xray_Quantified_Scaled
A1: Scaling of X-ray Quantified Data based on the Gravimetric Absorption Water Content at 7h | PINN Input
A2: Adopted Constant Scaling Factor: | F2: =0.805 -> 0.805
A3: Time(min) / Dist. From bottom ROI (cm) | B3: 0 | C3: 0.00316 | D3: 0.00633 | E3: 0.00949 | F3: 0.01265 | G3: 0.01582 | H3: 0.01898 | I3: 0.02214 | J3: 0.0253 | K3: 0.02847 | L3: 0.03163 | M3: 0.03479 | N3: 0.03796 | O3: 0.04112 | P3: 0.04428 | Q3: 0.04744 | R3: 0.05061 | S3: 0.05377 | T3: 0.05693 | U3: 0.0601 | V3: 0.06326 | W3: 0.06642 | X3: 0.06959 | Y3: 0.07275 | Z3: 0.07591 | AA3: 0.07908 | AB3: 0.08224 | AC3: 0.0854 | AD3: 0.08856 | AE3: 0.09173 | AF3: 0.09489 | AG3: 0.09805 | AH3: 0.10122 | AI3: 0.10438 | AJ3: 0.10754 | AK3: 0.1107 | AL3: 0.11387 | AM3: 0.11703 | AN3: 0.12019 | AO3: 0.12336 | AP3: 0.12652 | AQ3: 0.12968 | AR3: 0.13285 | AS3: 0.13601 | AT3: 0.13917 | AU3: 0.14233 | AV3: 0.1455 | AW3: 0.14866 | AX3: 0.15182 | AY3: 0.15499 | AZ3: 0.15815 | BA3: 0.16131 | BB3: 0.16448 | BC3: 0.16764 | BD3: 0.1708 | BE3: 0.17396 | BF3: 0.17713 | BG3: 0.18029 | BH3: 0.18345 | BI3: 0.18662 | BJ3: 0.18978 | BK3: 0.19294 | BL3: 0.19611 | BM3: 0.19927 | BN3: 0.20243 | BO3: 0.20559 | BP3: 0.20876 | BQ3: 0.21192 | BR3: 0.21508 | BS3: 0.21825 | BT3: 0.22141 | BU3: 0.22457 | BV3: 0.22774 | BW3: 0.2309 | BX3: 0.23406 | BY3: 0.23722 | BZ3: 0.24039 | CA3: 0.24355 | CB3: 0.24671 | CC3: 0.24988 | CD3: 0.25304 | CE3: 0.2562 | CF3: 0.25937 | CG3: 0.26253 | CH3: 0.26569 | CI3: 0.26885 | CJ3: 0.27202 | CK3: 0.27518 | CL3: 0.27834 | CM3: 0.28151 | CN3: 0.28467 | CO3: 0.28783 | CP3: 0.291 | CQ3: 0.29416 | CR3: 0.29732 | CS3: 0.30048 | CT3: 0.30365 | CU3: 0.30681 | CV3: 0.30997 | CW3: 0.31314 | CX3: 0.3163 | CY3: 0.31946 | CZ3: 0.32263 | DA3: 0.32579 | DB3: 0.32895 | DC3: 0.33212 | DD3: 0.33528 | DE3: 0.33844 | DF3: 0.3416 | DG3: 0.34477 | DH3: 0.34793 | DI3: 0.35109 | DJ3: 0.35426 | DK3: 0.35742 | DL3: 0.36058 | DM3: 0.36374 | DN3: 0.36691 | DO3: 0.37007 | DP3: 0.37323 | DQ3: 0.3764 | DR3: 0.37956 | DS3: 0.38272 | DT3: 0.38589 | DU3: 0.38905 | DV3: 0.39221 | DW3: 0.39538 | DX3: 0.39854 | DY3: 0.4017 | DZ3: 0.40486 | EA3: 0.40803 | EB3: 0.41119 | EC3: 0.41435 | ED3: 0.41752 | EE3: 0.42068 | EF3: 0.42384 | EG3: 0.427 | EH3: 0.43017 | EI3: 0.43333 | EJ3: 0.43649 | EK3: 0.43966 | EL3: 0.44282 | EM3: 0.44598 | EN3: 0.44915 | EO3: 0.45231 | EP3: 0.45547 | EQ3: 0.45863 | ER3: 0.4618 | ES3: 0.46496 | ET3: 0.46812 | EU3: 0.47129 | EV3: 0.47445 | EW3: 0.47761 | EX3: 0.48078 | EY3: 0.48394 | EZ3: 0.4871 | FA3: 0.49026 | FB3: 0.49343 | FC3: 0.49659 | FD3: 0.49975 | FE3: 0.50292 | FF3: 0.50608 | FG3: 0.50924 | FH3: 0.51241 | FI3: 0.51557 | FJ3: 0.51873 | FK3: 0.5219 | FL3: 0.52506 | FM3: 0.52822 | FN3: 0.53138 | FO3: 0.53455 | FP3: 0.53771 | FQ3: 0.54087 | FR3: 0.54404 | FS3: 0.5472 | FT3: 0.55036 | FU3: 0.55353 | FV3: 0.55669 | FW3: 0.55985 | FX3: 0.56301 | FY3: 0.56618 | FZ3: 0.56934 | GA3: 0.5725 | GB3: 0.57567 | GC3: 0.57883 | GD3: 0.58199 | GE3: 0.58516 | GF3: 0.58832 | GG3: 0.59148 | GH3: 0.59464 | GI3: 0.59781 | GJ3: 0.60097 | GK3: 0.60413 | GL3: 0.6073 | GM3: 0.61046 | GN3: 0.61362 | GO3: 0.61678 | GP3: 0.61995 | GQ3: 0.62311 | GR3: 0.62627 | GS3: 0.62944 | GT3: 0.6326 | GU3: 0.63576 | GV3: 0.63893 | GW3: 0.64209 | GX3: 0.64525 | GY3: 0.64842 | GZ3: 0.65158 | HA3: 0.65474 | HB3: 0.6579 | HC3: 0.66107 | HD3: 0.66423 | HE3: 0.66739 | HF3: 0.67056 | HG3: 0.67372 | HH3: 0.67688 | HI3: 0.68004 | HJ3: 0.68321 | HK3: 0.68637 | HL3: 0.68953 | HM3: 0.6927 | HN3: 0.69586 | HO3: 0.69902 | HP3: 0.70219 | HQ3: 0.70535 | HR3: 0.70851 | HS3: 0.71168 | HT3: 0.71484 | HU3: 0.718 | HV3: 0.72116 | HW3: 0.72433 | HX3: 0.72749 | HY3: 0.73065 | HZ3: 0.73382 | IA3: 0.73698 | IB3: 0.74014 | IC3: 0.7433 | ID3: 0.74647 | IE3: 0.74963 | IF3: 0.75279 | IG3: 0.75596 | IH3: 0.75912 | II3: 0.76228 | IJ3: 0.76545 | IK3: 0.76861 | IL3: 0.77177 | IM3: 0.77494 | IN3: 0.7781 | IO3: 0.78126 | IP3: 0.78442 | IQ3: 0.78759 | IR3: 0.79075 | IS3: 0.79391 | IT3: 0.79708 | IU3: 0.80024 | IV3: 0.8034 | IW3: 0.80656 | IX3: 0.80973 | IY3: 0.81289 | IZ3: 0.81605 | JA3: 0.81922 | JB3: 0.82238 | JC3: 0.82554 | JD3: 0.82871 | JE3: 0.83187 | JF3: 0.83503 | JG3: 0.83819 | JH3: 0.84136 | JI3: 0.84452 | JJ3: 0.84768 | JK3: 0.85085 | JL3: 0.85401 | JM3: 0.85717 | JN3: 0.86034 | JO3: 0.8635 | JP3: 0.86666 | JQ3: 0.86982 | JR3: 0.87299 | JS3: 0.87615 | JT3: 0.87931 | JU3: 0.88248 | JV3: 0.88564 | JW3: 0.8888 | JX3: 0.89197 | JY3: 0.89513 | JZ3: 0.89829 | KA3: 0.90145 | KB3: 0.90462 | KC3: 0.90778 | KD3: 0.91094 | KE3: 0.91411 | KF3: 0.91727 | KG3: 0.92043 | KH3: 0.9236 | KI3: 0.92676 | KJ3: 0.92992 | KK3: 0.93308 | KL3: 0.93625 | KM3: 0.93941 | KN3: 0.94257 | KO3: 0.94574 | KP3: 0.9489 | KQ3: 0.95206 | KR3: 0.95523 | KS3: 0.95839 | KT3: 0.96155 | KU3: 0.96472 | KV3: 0.96788 | KW3: 0.97104 | KX3: 0.9742 | KY3: 0.97737 | KZ3: 0.98053 | LA3: 0.98369 | LB3: 0.98686 | LC3: 0.99002 | LD3: 0.99318 | LE3: 0.99634 | LF3: 0.99951 | LG3: 1.00267 | LH3: 1.00583 | LI3: 1.009 | LJ3: 1.01216 | LK3: 1.01532 | LL3: 1.01849 | LM3: 1.02165 | LN3: 1.02481 | LO3: 1.02798 | LP3: 1.03114 | LQ3: 1.0343 | LR3: 1.03746 | LS3: 1.04063 | LT3: 1.04379 | LU3: 1.04695 | LV3: 1.05012 | LW3: 1.05328 | LX3: 1.05644 | LY3: 1.0596 | LZ3: 1.06277 | MA3: 1.06593 | MB3: 1.06909 | MC3: 1.07226 | MD3: 1.07542 | ME3: 1.07858 | MF3: 1.08175 | MG3: 1.08491 | MH3: 1.08807 | MI3: 1.09124 | MJ3: 1.0944 | MK3: 1.09756 | ML3: 1.10072 | MM3: 1.10389 | MN3: 1.10705 | MO3: 1.11021 | MP3: 1.11338 | MQ3: 1.11654 | MR3: 1.1197 | MS3: 1.12286 | MT3: 1.12603 | MU3: 1.12919 | MV3: 1.13235 | MW3: 1.13552 | MX3: 1.13868 | MY3: 1.14184 | MZ3: 1.14501 | NA3: 1.14817 | NB3: 1.15133 | NC3: 1.15449 | ND3: 1.15766 | NE3: 1.16082 | NF3: 1.16398 | NG3: 1.16715 | NH3: 1.17031 | NI3: 1.17347 | NJ3: 1.17664 | NK3: 1.1798 | NL3: 1.18296 | NM3: 1.18613 | NN3: 1.18929 | NO3: 1.19245 | NP3: 1.19561 | NQ3: 1.19878 | NR3: 1.20194 | NS3: 1.2051 | NT3: 1.20827 | NU3: 1.21143 | NV3: 1.21459 | NW3: 1.21775 | NX3: 1.22092 | NY3: 1.22408 | NZ3: 1.22724 | OA3: 1.23041 | OB3: 1.23357 | OC3: 1.23673 | OD3: 1.2399 | OE3: 1.24306 | OF3: 1.24622 | OG3: 1.24938 | OH3: 1.25255 | OI3: 1.25571 | OJ3: 1.25887 | OK3: 1.26204 | OL3: 1.2652 | OM3: 1.26836 | ON3: 1.27153 | OO3: 1.27469 | OP3: 1.27785 | OQ3: 1.28102 | OR3: 1.28418 | OS3: 1.28734 | OT3: 1.2905 | OU3: 1.29367 | OV3: 1.29683 | OW3: 1.29999 | OX3: 1.30316 | OY3: 1.30632 | OZ3: 1.30948 | PA3: 1.31264 | PB3: 1.31581 | PC3: 1.31897 | PD3: 1.32213 | PE3: 1.3253 | PF3: 1.32846 | PG3: 1.33162 | PH3: 1.33479 | PI3: 1.33795 | PJ3: 1.34111 | PK3: 1.34428 | PL3: 1.34744 | PM3: 1.3506 | PN3: 1.35376 | PO3: 1.35693 | PP3: 1.36009 | PQ3: 1.36325 | PR3: 1.36642 | PS3: 1.36958 | PT3: 1.37274 | PU3: 1.3759 | PV3: 1.37907 | PW3: 1.38223 | PX3: 1.38539 | PY3: 1.38856 | PZ3: 1.39172 | QA3: 1.39488 | QB3: 1.39805 | QC3: 1.40121 | QD3: 1.40437 | QE3: 1.40754 | QF3: 1.4107 | QG3: 1.41386 | QH3: 1.41702 | QI3: 1.42019 | QJ3: 1.42335 | QK3: 1.42651 | QL3: 1.42968 | QM3: 1.43284 | QN3: 1.436 | QO3: 1.43916 | QP3: 1.44233 | QQ3: 1.44549 | QR3: 1.44865 | QS3: 1.45182 | QT3: 1.45498 | QU3: 1.45814 | QV3: 1.46131 | QW3: 1.46447 | QX3: 1.46763 | QY3: 1.47079 | QZ3: 1.47396 | RA3: 1.47712 | RB3: 1.48028 | RC3: 1.48345 | RD3: 1.48661 | RE3: 1.48977 | RF3: 1.49294 | RG3: 1.4961 | RH3: 1.49926 | RI3: 1.50242 | RJ3: 1.50559 | RK3: 1.50875 | RL3: 1.51191 | RM3: 1.51508 | RN3: 1.51824 | RO3: 1.5214 | RP3: 1.52457 | RQ3: 1.52773 | RR3: 1.53089 | RS3: 1.53406 | RT3: 1.53722 | RU3: 1.54038 | RV3: 1.54354 | RW3: 1.54671 | RX3: 1.54987 | RY3: 1.55303 | RZ3: 1.5562 | SA3: 1.55936 | SB3: 1.56252 | SC3: 1.56568 | SD3: 1.56885 | SE3: 1.57201 | SF3: 1.57517 | SG3: 1.57834 | SH3: 1.5815 | SI3: 1.58466 | SJ3: 1.58783 | SK3: 1.59099 | SL3: 1.59415 | SM3: 1.59732 | SN3: 1.60048 | SO3: 1.60364 | SP3: 1.6068 | SQ3: 1.60997 | SR3: 1.61313 | SS3: 1.61629 | ST3: 1.61946 | SU3: 1.62262 | SV3: 1.62578 | SW3: 1.62894 | SX3: 1.63211 | SY3: 1.63527 | SZ3: 1.63843 | TA3: 1.6416 | TB3: 1.64476 | TC3: 1.64792 | TD3: 1.65109 | TE3: 1.65425 | TF3: 1.65741 | TG3: 1.66058 | TH3: 1.66374 | TI3: 1.6669 | TJ3: 1.67006 | TK3: 1.67323 | TL3: 1.67639 | TM3: 1.67955 | TN3: 1.68272 | TO3: 1.68588 | TP3: 1.68904 | TQ3: 1.6922 | TR3: 1.69537 | TS3: 1.69853 | TT3: 1.70169 | TU3: 1.70486 | TV3: 1.70802 | TW3: 1.71118 | TX3: 1.71435 | TY3: 1.71751 | TZ3: 1.72067 | UA3: 1.72383 | UB3: 1.727 | UC3: 1.73016 | UD3: 1.73332 | UE3: 1.73649 | UF3: 1.73965 | UG3: 1.74281 | UH3: 1.74598 | UI3: 1.74914 | UJ3: 1.7523 | UK3: 1.75546 | UL3: 1.75863 | UM3: 1.76179 | UN3: 1.76495 | UO3: 1.76812 | UP3: 1.77128 | UQ3: 1.77444 | UR3: 1.77761 | US3: 1.78077 | UT3: 1.78393 | UU3: 1.7871 | UV3: 1.79026 | UW3: 1.79342 | UX3: 1.79658 | UY3: 1.79975 | UZ3: 1.80291 | VA3: 1.80607 | VB3: 1.80924 | VC3: 1.8124 | VD3: 1.81556 | VE3: 1.81872 | VF3: 1.82189 | VG3: 1.82505 | VH3: 1.82821 | VI3: 1.83138 | VJ3: 1.83454 | VK3: 1.8377 | VL3: 1.84087 | VM3: 1.84403 | VN3: 1.84719 | VO3: 1.85036 | VP3: 1.85352 | VQ3: 1.85668 | VR3: 1.85984 | VS3: 1.86301 | VT3: 1.86617 | VU3: 1.86933 | VV3: 1.8725 | VW3: 1.87566 | VX3: 1.87882 | VY3: 1.88198 | VZ3: 1.88515 | WA3: 1.88831 | WB3: 1.89147 | WC3: 1.89464 | WD3: 1.8978 | WE3: 1.90096 | WF3: 1.90413 | WG3: 1.90729 | WH3: 1.91045 | WI3: 1.91361 | WJ3: 1.91678 | WK3: 1.91994 | WL3: 1.9231 | WM3: 1.92627 | WN3: 1.92943 | WO3: 1.93259 | WP3: 1.93576 | WQ3: 1.93892 | WR3: 1.94208 | WS3: 1.94524 | WT3: 1.94841 | WU3: 1.95157 | WV3: 1.95473 | WW3: 1.9579 | WX3: 1.96106 | WY3: 1.96422 | WZ3: 1.96739 | XA3: 1.97055 | XB3: 1.97371 | XC3: 1.97688 | XD3: 1.98004 | XE3: 1.9832 | XF3: 1.98636 | XG3: 1.98953 | XH3: 1.99269 | XI3: 1.99585 | XJ3: 1.99902 | XK3: 2.00218 | XL3: 2.00534 | XM3: 2.0085 | XN3: 2.01167 | XO3: 2.01483 | XP3: 2.01799 | XQ3: 2.02116 | XR3: 2.02432 | XS3: 2.02748 | XT3: 2.03065 | XU3: 2.03381 | XV3: 2.03697 | XW3: 2.04013 | XX3: 2.0433 | XY3: 2.04646 | XZ3: 2.04962 | YA3: 2.05279 | YB3: 2.05595 | YC3: 2.05911 | YD3: 2.06228 | YE3: 2.06544 | YF3: 2.0686 | YG3: 2.07176 | YH3: 2.07493 | YI3: 2.07809 | YJ3: 2.08125 | YK3: 2.08442 | YL3: 2.08758 | YM3: 2.09074 | YN3: 2.09391 | YO3: 2.09707 | YP3: 2.10023 | YQ3: 2.1034 | YR3: 2.10656 | YS3: 2.10972 | YT3: 2.11288 | YU3: 2.11605 | YV3: 2.11921 | YW3: 2.12237 | YX3: 2.12554 | YY3: 2.1287 | YZ3: 2.13186 | ZA3: 2.13503 | ZB3: 2.13819 | ZC3: 2.14135 | ZD3: 2.14451 | ZE3: 2.14768 | ZF3: 2.15084 | ZG3: 2.154 | ZH3: 2.15717 | ZI3: 2.16033 | ZJ3: 2.16349 | ZK3: 2.16666 | ZL3: 2.16982 | ZM3: 2.17298 | ZN3: 2.17614 | ZO3: 2.17931 | ZP3: 2.18247 | ZQ3: 2.18563 | ZR3: 2.1888 | ZS3: 2.19196 | ZT3: 2.19512 | ZU3: 2.19828 | ZV3: 2.20145 | ZW3: 2.20461 | ZX3: 2.20777 | ZY3: 2.21094 | ZZ3: 2.2141 | AAA3: 2.21726 | AAB3: 2.22043 | AAC3: 2.22359 | AAD3: 2.22675 | AAE3: 2.22991 | AAF3: 2.23308 | AAG3: 2.23624 | AAH3: 2.2394 | AAI3: 2.24257 | AAJ3: 2.24573 | AAK3: 2.24889 | AAL3: 2.25206 | AAM3: 2.25522 | AAN3: 2.25838 | AAO3: 2.26154 | AAP3: 2.26471 | AAQ3: 2.26787 | AAR3: 2.27103 | AAS3: 2.2742 | AAT3: 2.27736 | AAU3: 2.28052 | AAV3: 2.28369 | AAW3: 2.28685 | AAX3: 2.29001 | AAY3: 2.29318 | AAZ3: 2.29634 | ABA3: 2.2995 | ABB3: 2.30266 | ABC3: 2.30583 | ABD3: 2.30899 | ABE3: 2.31215 | ABF3: 2.31532 | ABG3: 2.31848 | ABH3: 2.32164 | ABI3: 2.3248 | ABJ3: 2.32797 | ABK3: 2.33113 | ABL3: 2.33429 | ABM3: 2.33746 | ABN3: 2.34062 | ABO3: 2.34378 | ABP3: 2.34695 | ABQ3: 2.35011 | ABR3: 2.35327 | ABS3: 2.35643 | ABT3: 2.3596 | ABU3: 2.36276 | ABV3: 2.36592 | ABW3: 2.36909 | ABX3: 2.37225 | ABY3: 2.37541 | ABZ3: 2.37858 | ACA3: 2.38174 | ACB3: 2.3849 | ACC3: 2.38806 | ACD3: 2.39123 | ACE3: 2.39439 | ACF3: 2.39755 | ACG3: 2.40072 | ACH3: 2.40388 | ACI3: 2.40704 | ACJ3: 2.41021 | ACK3: 2.41337 | ACL3: 2.41653 | ACM3: 2.4197 | ACN3: 2.42286 | ACO3: 2.42602 | ACP3: 2.42918 | ACQ3: 2.43235 | ACR3: 2.43551 | ACS3: 2.43867 | ACT3: 2.44184 | ACU3: 2.445 | ACV3: 2.44816 | ACW3: 2.45133 | ACX3: 2.45449 | ACY3: 2.45765 | ACZ3: 2.46081 | ADA3: 2.46398 | ADB3: 2.46714 | ADC3: 2.4703 | ADD3: 2.47347 | ADE3: 2.47663 | ADF3: 2.47979 | ADG3: 2.48296 | ADH3: 2.48612 | ADI3: 2.48928 | ADJ3: 2.49244 | ADK3: 2.49561 | ADL3: 2.49877 | ADM3: 2.50193 | ADN3: 2.5051 | ADO3: 2.50826 | ADP3: 2.51142 | ADQ3: 2.51458 | ADR3: 2.51775 | ADS3: 2.52091 | ADT3: 2.52407 | ADU3: 2.52724 | ADV3: 2.5304 | ADW3: 2.53356 | ADX3: 2.53673 | ADY3: 2.53989 | ADZ3: 2.54305 | AEA3: 2.54621 | AEB3: 2.54938 | AEC3: 2.55254 | AED3: 2.5557 | AEE3: 2.55887 | AEF3: 2.56203 | AEG3: 2.56519 | AEH3: 2.56836 | AEI3: 2.57152 | AEJ3: 2.57468 | AEK3: 2.57784 | AEL3: 2.58101 | AEM3: 2.58417 | AEN3: 2.58733 | AEO3: 2.5905 | AEP3: 2.59366 | AEQ3: 2.59682 | AER3: 2.59999 | AES3: 2.60315 | AET3: 2.60631 | AEU3: 2.60948 | AEV3: 2.61264 | AEW3: 2.6158 | AEX3: 2.61896 | AEY3: 2.62213 | AEZ3: 2.62529 | AFA3: 2.62845 | AFB3: 2.63162 | AFC3: 2.63478 | AFD3: 2.63794 | AFE3: 2.6411 | AFF3: 2.64427 | AFG3: 2.64743 | AFH3: 2.65059 | AFI3: 2.65376 | AFJ3: 2.65692 | AFK3: 2.66008 | AFL3: 2.66325 | AFM3: 2.66641 | AFN3: 2.66957 | AFO3: 2.67274 | AFP3: 2.6759 | AFQ3: 2.67906 | AFR3: 2.68222 | AFS3: 2.68539 | AFT3: 2.68855 | AFU3: 2.69171 | AFV3: 2.69488 | AFW3: 2.69804 | AFX3: 2.7012 | AFY3: 2.70436 | AFZ3: 2.70753 | AGA3: 2.71069 | AGB3: 2.71385 | AGC3: 2.71702 | AGD3: 2.72018 | AGE3: 2.72334 | AGF3: 2.72651 | AGG3: 2.72967 | AGH3: 2.73283 | AGI3: 2.736 | AGJ3: 2.73916 | AGK3: 2.74232 | AGL3: 2.74548 | AGM3: 2.74865 | AGN3: 2.75181 | AGO3: 2.75497 | AGP3: 2.75814 | AGQ3: 2.7613 | AGR3: 2.76446 | AGS3: 2.76762 | AGT3: 2.77079 | AGU3: 2.77395 | AGV3: 2.77711 | AGW3: 2.78028 | AGX3: 2.78344 | AGY3: 2.7866 | AGZ3: 2.78977 | AHA3: 2.79293 | AHB3: 2.79609 | AHC3: 2.79926 | AHD3: 2.80242 | AHE3: 2.80558 | AHF3: 2.80874 | AHG3: 2.81191 | AHH3: 2.81507 | AHI3: 2.81823 | AHJ3: 2.8214 | AHK3: 2.82456 | AHL3: 2.82772 | AHM3: 2.83088 | AHN3: 2.83405 | AHO3: 2.83721 | AHP3: 2.84037 | AHQ3: 2.84354
A4: 1.5 | B4: =HS_Xray_Quantified_Lin_attn!B4*HS_Xray_Quantified_Scaled!$F$2 -> 0.41530913 | C4: =HS_Xray_Quantified_Lin_attn!C4*HS_Xray_Quantified_Scaled!$F$2 -> 0.41445028 | D4: =HS_Xray_Quantified_Lin_attn!D4*HS_Xray_Quantified_Scaled!$F$2 -> 0.41356574 | E4: =HS_Xray_Quantified_Lin_attn!E4*HS_Xray_Quantified_Scaled!$F$2 -> 0.41266011 | F4: =HS_Xray_Quantified_Lin_attn!F4*HS_Xray_Quantified_Scaled!$F$2 -> 0.41173864 | G4: =HS_Xray_Quantified_Lin_attn!G4*HS_Xray_Quantified_Scaled!$F$2 -> 0.41080679 | H4: =HS_Xray_Quantified_Lin_attn!H4*HS_Xray_Quantified_Scaled!$F$2 -> 0.40986958 | I4: =HS_Xray_Quantified_Lin_attn!I4*HS_Xray_Quantified_Scaled!$F$2 -> 0.40893176 | ... AHQ4: =HS_Xray_Quantified_Lin_attn!AHQ4*HS_Xray_Quantified_Scaled!$F$2 -> 0.0076219467
A5: 2.5 | B5: =HS_Xray_Quantified_Lin_attn!B5*HS_Xray_Quantified_Scaled!$F$2 -> 0.41928555 | C5: =HS_Xray_Quantified_Lin_attn!C5*HS_Xray_Quantified_Scaled!$F$2 -> 0.41857954 | D5: =HS_Xray_Quantified_Lin_attn!D5*HS_Xray_Quantified_Scaled!$F$2 -> 0.41786065 | E5: =HS_Xray_Quantified_Lin_attn!E5*HS_Xray_Quantified_Scaled!$F$2 -> 0.41713482 | F5: =HS_Xray_Quantified_Lin_attn!F5*HS_Xray_Quantified_Scaled!$F$2 -> 0.41640886 | G5: =HS_Xray_Quantified_Lin_attn!G5*HS_Xray_Quantified_Scaled!$F$2 -> 0.41569007 | H5: =HS_Xray_Quantified_Lin_attn!H5*HS_Xray_Quantified_Scaled!$F$2 -> 0.41498565 | I5: =HS_Xray_Quantified_Lin_attn!I5*HS_Xray_Quantified_Scaled!$F$2 -> 0.41430274 | ... AHQ5: =HS_Xray_Quantified_Lin_attn!AHQ5*HS_Xray_Quantified_Scaled!$F$2 -> 0.004871503
A6: 3.5 | B6: =HS_Xray_Quantified_Lin_attn!B6*HS_Xray_Quantified_Scaled!$F$2 -> 0.42174053 | C6: =HS_Xray_Quantified_Lin_attn!C6*HS_Xray_Quantified_Scaled!$F$2 -> 0.42112761 | D6: =HS_Xray_Quantified_Lin_attn!D6*HS_Xray_Quantified_Scaled!$F$2 -> 0.42050529 | E6: =HS_Xray_Quantified_Lin_attn!E6*HS_Xray_Quantified_Scaled!$F$2 -> 0.41987844 | F6: =HS_Xray_Quantified_Lin_attn!F6*HS_Xray_Quantified_Scaled!$F$2 -> 0.41925272 | G6: =HS_Xray_Quantified_Lin_attn!G6*HS_Xray_Quantified_Scaled!$F$2 -> 0.41863438 | H6: =HS_Xray_Quantified_Lin_attn!H6*HS_Xray_Quantified_Scaled!$F$2 -> 0.41802946 | I6: =HS_Xray_Quantified_Lin_attn!I6*HS_Xray_Quantified_Scaled!$F$2 -> 0.4174442 | ... AHQ6: =HS_Xray_Quantified_Lin_attn!AHQ6*HS_Xray_Quantified_Scaled!$F$2 -> 0.0014449372
A7: 5 | B7: =HS_Xray_Quantified_Lin_attn!B7*HS_Xray_Quantified_Scaled!$F$2 -> 0.4228741 | C7: =HS_Xray_Quantified_Lin_attn!C7*HS_Xray_Quantified_Scaled!$F$2 -> 0.42232314 | D7: =HS_Xray_Quantified_Lin_attn!D7*HS_Xray_Quantified_Scaled!$F$2 -> 0.42177222 | E7: =HS_Xray_Quantified_Lin_attn!E7*HS_Xray_Quantified_Scaled!$F$2 -> 0.42122826 | F7: =HS_Xray_Quantified_Lin_attn!F7*HS_Xray_Quantified_Scaled!$F$2 -> 0.42069826 | G7: =HS_Xray_Quantified_Lin_attn!G7*HS_Xray_Quantified_Scaled!$F$2 -> 0.42018888 | H7: =HS_Xray_Quantified_Lin_attn!H7*HS_Xray_Quantified_Scaled!$F$2 -> 0.41970585 | I7: =HS_Xray_Quantified_Lin_attn!I7*HS_Xray_Quantified_Scaled!$F$2 -> 0.41925417 | ... AHQ7: =HS_Xray_Quantified_Lin_attn!AHQ7*HS_Xray_Quantified_Scaled!$F$2 -> 0.0043777799
A8: 7.167 | B8: =HS_Xray_Quantified_Lin_attn!B8*HS_Xray_Quantified_Scaled!$F$2 -> 0.42467235 | C8: =HS_Xray_Quantified_Lin_attn!C8*HS_Xray_Quantified_Scaled!$F$2 -> 0.42411418 | D8: =HS_Xray_Quantified_Lin_attn!D8*HS_Xray_Quantified_Scaled!$F$2 -> 0.42354135 | E8: =HS_Xray_Quantified_Lin_attn!E8*HS_Xray_Quantified_Scaled!$F$2 -> 0.42296275 | F8: =HS_Xray_Quantified_Lin_attn!F8*HS_Xray_Quantified_Scaled!$F$2 -> 0.42238832 | G8: =HS_Xray_Quantified_Lin_attn!G8*HS_Xray_Quantified_Scaled!$F$2 -> 0.42182823 | H8: =HS_Xray_Quantified_Lin_attn!H8*HS_Xray_Quantified_Scaled!$F$2 -> 0.42129188 | I8: =HS_Xray_Quantified_Lin_attn!I8*HS_Xray_Quantified_Scaled!$F$2 -> 0.42078774 | ... AHQ8: =HS_Xray_Quantified_Lin_attn!AHQ8*HS_Xray_Quantified_Scaled!$F$2 -> 0.0055988203
A9: 8 | B9: =HS_Xray_Quantified_Lin_attn!B9*HS_Xray_Quantified_Scaled!$F$2 -> 0.42410604 | C9: =HS_Xray_Quantified_Lin_attn!C9*HS_Xray_Quantified_Scaled!$F$2 -> 0.42363978 | D9: =HS_Xray_Quantified_Lin_attn!D9*HS_Xray_Quantified_Scaled!$F$2 -> 0.42315924 | E9: =HS_Xray_Quantified_Lin_attn!E9*HS_Xray_Quantified_Scaled!$F$2 -> 0.42267048 | F9: =HS_Xray_Quantified_Lin_attn!F9*HS_Xray_Quantified_Scaled!$F$2 -> 0.42218053 | G9: =HS_Xray_Quantified_Lin_attn!G9*HS_Xray_Quantified_Scaled!$F$2 -> 0.42169705 | H9: =HS_Xray_Quantified_Lin_attn!H9*HS_Xray_Quantified_Scaled!$F$2 -> 0.42122729 | I9: =HS_Xray_Quantified_Lin_attn!I9*HS_Xray_Quantified_Scaled!$F$2 -> 0.42077816 | ... AHQ9: =HS_Xray_Quantified_Lin_attn!AHQ9*HS_Xray_Quantified_Scaled!$F$2 -> 0.0054243188
A10: 9 | B10: =HS_Xray_Quantified_Lin_attn!B10*HS_Xray_Quantified_Scaled!$F$2 -> 0.4243249 | C10: =HS_Xray_Quantified_Lin_attn!C10*HS_Xray_Quantified_Scaled!$F$2 -> 0.42383266 | D10: =HS_Xray_Quantified_Lin_attn!D10*HS_Xray_Quantified_Scaled!$F$2 -> 0.42334774 | E10: =HS_Xray_Quantified_Lin_attn!E10*HS_Xray_Quantified_Scaled!$F$2 -> 0.42287512 | F10: =HS_Xray_Quantified_Lin_attn!F10*HS_Xray_Quantified_Scaled!$F$2 -> 0.42242019 | G10: =HS_Xray_Quantified_Lin_attn!G10*HS_Xray_Quantified_Scaled!$F$2 -> 0.42198855 | H10: =HS_Xray_Quantified_Lin_attn!H10*HS_Xray_Quantified_Scaled!$F$2 -> 0.42158507 | I10: =HS_Xray_Quantified_Lin_attn!I10*HS_Xray_Quantified_Scaled!$F$2 -> 0.42121435 | ... AHQ10: =HS_Xray_Quantified_Lin_attn!AHQ10*HS_Xray_Quantified_Scaled!$F$2 -> 0.006103524
A11: 10 | B11: =HS_Xray_Quantified_Lin_attn!B11*HS_Xray_Quantified_Scaled!$F$2 -> 0.42459298 | C11: =HS_Xray_Quantified_Lin_attn!C11*HS_Xray_Quantified_Scaled!$F$2 -> 0.42408469 | D11: =HS_Xray_Quantified_Lin_attn!D11*HS_Xray_Quantified_Scaled!$F$2 -> 0.42356852 | E11: =HS_Xray_Quantified_Lin_attn!E11*HS_Xray_Quantified_Scaled!$F$2 -> 0.42305128 | F11: =HS_Xray_Quantified_Lin_attn!F11*HS_Xray_Quantified_Scaled!$F$2 -> 0.42254049 | G11: =HS_Xray_Quantified_Lin_attn!G11*HS_Xray_Quantified_Scaled!$F$2 -> 0.42204408 | H11: =HS_Xray_Quantified_Lin_attn!H11*HS_Xray_Quantified_Scaled!$F$2 -> 0.4215694 | I11: =HS_Xray_Quantified_Lin_attn!I11*HS_Xray_Quantified_Scaled!$F$2 -> 0.42112344 | ... AHQ11: =HS_Xray_Quantified_Lin_attn!AHQ11*HS_Xray_Quantified_Scaled!$F$2 -> 0.0062733515
A12: 11 | B12: =HS_Xray_Quantified_Lin_attn!B12*HS_Xray_Quantified_Scaled!$F$2 -> 0.42353594 | C12: =HS_Xray_Quantified_Lin_attn!C12*HS_Xray_Quantified_Scaled!$F$2 -> 0.42310722 | D12: =HS_Xray_Quantified_Lin_attn!D12*HS_Xray_Quantified_Scaled!$F$2 -> 0.42267744 | E12: =HS_Xray_Quantified_Lin_attn!E12*HS_Xray_Quantified_Scaled!$F$2 -> 0.42224963 | F12: =HS_Xray_Quantified_Lin_attn!F12*HS_Xray_Quantified_Scaled!$F$2 -> 0.42182745 | G12: =HS_Xray_Quantified_Lin_attn!G12*HS_Xray_Quantified_Scaled!$F$2 -> 0.4214152 | H12: =HS_Xray_Quantified_Lin_attn!H12*HS_Xray_Quantified_Scaled!$F$2 -> 0.42101689 | I12: =HS_Xray_Quantified_Lin_attn!I12*HS_Xray_Quantified_Scaled!$F$2 -> 0.42063675 | ... AHQ12: =HS_Xray_Quantified_Lin_attn!AHQ12*HS_Xray_Quantified_Scaled!$F$2 -> 0.0029539089
A13: 12 | B13: =HS_Xray_Quantified_Lin_attn!B13*HS_Xray_Quantified_Scaled!$F$2 -> 0.42415796 | C13: =HS_Xray_Quantified_Lin_attn!C13*HS_Xray_Quantified_Scaled!$F$2 -> 0.42359658 | D13: =HS_Xray_Quantified_Lin_attn!D13*HS_Xray_Quantified_Scaled!$F$2 -> 0.42302798 | E13: =HS_Xray_Quantified_Lin_attn!E13*HS_Xray_Quantified_Scaled!$F$2 -> 0.42246119 | F13: =HS_Xray_Quantified_Lin_attn!F13*HS_Xray_Quantified_Scaled!$F$2 -> 0.4219059 | G13: =HS_Xray_Quantified_Lin_attn!G13*HS_Xray_Quantified_Scaled!$F$2 -> 0.42137216 | H13: =HS_Xray_Quantified_Lin_attn!H13*HS_Xray_Quantified_Scaled!$F$2 -> 0.42086907 | I13: =HS_Xray_Quantified_Lin_attn!I13*HS_Xray_Quantified_Scaled!$F$2 -> 0.4204052 | ... AHQ13: =HS_Xray_Quantified_Lin_attn!AHQ13*HS_Xray_Quantified_Scaled!$F$2 -> 0.0042713764
A14: 13.5 | B14: =HS_Xray_Quantified_Lin_attn!B14*HS_Xray_Quantified_Scaled!$F$2 -> 0.42264086 | C14: =HS_Xray_Quantified_Lin_attn!C14*HS_Xray_Quantified_Scaled!$F$2 -> 0.42209929 | D14: =HS_Xray_Quantified_Lin_attn!D14*HS_Xray_Quantified_Scaled!$F$2 -> 0.42155579 | E14: =HS_Xray_Quantified_Lin_attn!E14*HS_Xray_Quantified_Scaled!$F$2 -> 0.42102051 | F14: =HS_Xray_Quantified_Lin_attn!F14*HS_Xray_Quantified_Scaled!$F$2 -> 0.42050419 | G14: =HS_Xray_Quantified_Lin_attn!G14*HS_Xray_Quantified_Scaled!$F$2 -> 0.42001744 | H14: =HS_Xray_Quantified_Lin_attn!H14*HS_Xray_Quantified_Scaled!$F$2 -> 0.41956976 | I14: =HS_Xray_Quantified_Lin_attn!I14*HS_Xray_Quantified_Scaled!$F$2 -> 0.41916938 | ... AHQ14: =HS_Xray_Quantified_Lin_attn!AHQ14*HS_Xray_Quantified_Scaled!$F$2 -> 0.0052765757
A15: 15 | B15: =HS_Xray_Quantified_Lin_attn!B15*HS_Xray_Quantified_Scaled!$F$2 -> 0.42303829 | C15: =HS_Xray_Quantified_Lin_attn!C15*HS_Xray_Quantified_Scaled!$F$2 -> 0.42265457 | D15: =HS_Xray_Quantified_Lin_attn!D15*HS_Xray_Quantified_Scaled!$F$2 -> 0.42227408 | E15: =HS_Xray_Quantified_Lin_attn!E15*HS_Xray_Quantified_Scaled!$F$2 -> 0.42190306 | F15: =HS_Xray_Quantified_Lin_attn!F15*HS_Xray_Quantified_Scaled!$F$2 -> 0.42154802 | G15: =HS_Xray_Quantified_Lin_attn!G15*HS_Xray_Quantified_Scaled!$F$2 -> 0.42121525 | H15: =HS_Xray_Quantified_Lin_attn!H15*HS_Xray_Quantified_Scaled!$F$2 -> 0.42091 | I15: =HS_Xray_Quantified_Lin_attn!I15*HS_Xray_Quantified_Scaled!$F$2 -> 0.42063662 | ... AHQ15: =HS_Xray_Quantified_Lin_attn!AHQ15*HS_Xray_Quantified_Scaled!$F$2 -> 0.0039042021
... A28: 60 | B28: =HS_Xray_Quantified_Lin_attn!B28*HS_Xray_Quantified_Scaled!$F$2 -> 0.42357409 | C28: =HS_Xray_Quantified_Lin_attn!C28*HS_Xray_Quantified_Scaled!$F$2 -> 0.42300268 | D28: =HS_Xray_Quantified_Lin_attn!D28*HS_Xray_Quantified_Scaled!$F$2 -> 0.42245432 | E28: =HS_Xray_Quantified_Lin_attn!E28*HS_Xray_Quantified_Scaled!$F$2 -> 0.42193981 | F28: =HS_Xray_Quantified_Lin_attn!F28*HS_Xray_Quantified_Scaled!$F$2 -> 0.42146991 | G28: =HS_Xray_Quantified_Lin_attn!G28*HS_Xray_Quantified_Scaled!$F$2 -> 0.42105439 | H28: =HS_Xray_Quantified_Lin_attn!H28*HS_Xray_Quantified_Scaled!$F$2 -> 0.42070126 | I28: =HS_Xray_Quantified_Lin_attn!I28*HS_Xray_Quantified_Scaled!$F$2 -> 0.42041636 | ... AHQ28: =HS_Xray_Quantified_Lin_attn!AHQ28*HS_Xray_Quantified_Scaled!$F$2 -> 0.23752344

Sheet HS_Xray_Quantified_Lin_attn
A1: Quantification by using the Equivalent Linear Attenuation Scaling Factor for water with 10mm thickness layer
A2: Total Attenuation Scaling Factor (10mm th): | F2: -5.44366
A3: Time(min) / Dist. From bottom ROI (cm) | B3: 0 | C3: 0.00316 | D3: 0.00633 | E3: 0.00949 | F3: 0.01265 | G3: 0.01582 | H3: 0.01898 | I3: 0.02214 | J3: 0.0253 | K3: 0.02847 | L3: 0.03163 | M3: 0.03479 | N3: 0.03796 | O3: 0.04112 | P3: 0.04428 | Q3: 0.04744 | R3: 0.05061 | S3: 0.05377 | T3: 0.05693 | U3: 0.0601 | V3: 0.06326 | W3: 0.06642 | X3: 0.06959 | Y3: 0.07275 | Z3: 0.07591 | AA3: 0.07908 | AB3: 0.08224 | AC3: 0.0854 | AD3: 0.08856 | AE3: 0.09173 | AF3: 0.09489 | AG3: 0.09805 | AH3: 0.10122 | AI3: 0.10438 | AJ3: 0.10754 | AK3: 0.1107 | AL3: 0.11387 | AM3: 0.11703 | AN3: 0.12019 | AO3: 0.12336 | AP3: 0.12652 | AQ3: 0.12968 | AR3: 0.13285 | AS3: 0.13601 | AT3: 0.13917 | AU3: 0.14233 | AV3: 0.1455 | AW3: 0.14866 | AX3: 0.15182 | AY3: 0.15499 | AZ3: 0.15815 | BA3: 0.16131 | BB3: 0.16448 | BC3: 0.16764 | BD3: 0.1708 | BE3: 0.17396 | BF3: 0.17713 | BG3: 0.18029 | BH3: 0.18345 | BI3: 0.18662 | BJ3: 0.18978 | BK3: 0.19294 | BL3: 0.19611 | BM3: 0.19927 | BN3: 0.20243 | BO3: 0.20559 | BP3: 0.20876 | BQ3: 0.21192 | BR3: 0.21508 | BS3: 0.21825 | BT3: 0.22141 | BU3: 0.22457 | BV3: 0.22774 | BW3: 0.2309 | BX3: 0.23406 | BY3: 0.23722 | BZ3: 0.24039 | CA3: 0.24355 | CB3: 0.24671 | CC3: 0.24988 | CD3: 0.25304 | CE3: 0.2562 | CF3: 0.25937 | CG3: 0.26253 | CH3: 0.26569 | CI3: 0.26885 | CJ3: 0.27202 | CK3: 0.27518 | CL3: 0.27834 | CM3: 0.28151 | CN3: 0.28467 | CO3: 0.28783 | CP3: 0.291 | CQ3: 0.29416 | CR3: 0.29732 | CS3: 0.30048 | CT3: 0.30365 | CU3: 0.30681 | CV3: 0.30997 | CW3: 0.31314 | CX3: 0.3163 | CY3: 0.31946 | CZ3: 0.32263 | DA3: 0.32579 | DB3: 0.32895 | DC3: 0.33212 | DD3: 0.33528 | DE3: 0.33844 | DF3: 0.3416 | DG3: 0.34477 | DH3: 0.34793 | DI3: 0.35109 | DJ3: 0.35426 | DK3: 0.35742 | DL3: 0.36058 | DM3: 0.36374 | DN3: 0.36691 | DO3: 0.37007 | DP3: 0.37323 | DQ3: 0.3764 | DR3: 0.37956 | DS3: 0.38272 | DT3: 0.38589 | DU3: 0.38905 | DV3: 0.39221 | DW3: 0.39538 | DX3: 0.39854 | DY3: 0.4017 | DZ3: 0.40486 | EA3: 0.40803 | EB3: 0.41119 | EC3: 0.41435 | ED3: 0.41752 | EE3: 0.42068 | EF3: 0.42384 | EG3: 0.427 | EH3: 0.43017 | EI3: 0.43333 | EJ3: 0.43649 | EK3: 0.43966 | EL3: 0.44282 | EM3: 0.44598 | EN3: 0.44915 | EO3: 0.45231 | EP3: 0.45547 | EQ3: 0.45863 | ER3: 0.4618 | ES3: 0.46496 | ET3: 0.46812 | EU3: 0.47129 | EV3: 0.47445 | EW3: 0.47761 | EX3: 0.48078 | EY3: 0.48394 | EZ3: 0.4871 | FA3: 0.49026 | FB3: 0.49343 | FC3: 0.49659 | FD3: 0.49975 | FE3: 0.50292 | FF3: 0.50608 | FG3: 0.50924 | FH3: 0.51241 | FI3: 0.51557 | FJ3: 0.51873 | FK3: 0.5219 | FL3: 0.52506 | FM3: 0.52822 | FN3: 0.53138 | FO3: 0.53455 | FP3: 0.53771 | FQ3: 0.54087 | FR3: 0.54404 | FS3: 0.5472 | FT3: 0.55036 | FU3: 0.55353 | FV3: 0.55669 | FW3: 0.55985 | FX3: 0.56301 | FY3: 0.56618 | FZ3: 0.56934 | GA3: 0.5725 | GB3: 0.57567 | GC3: 0.57883 | GD3: 0.58199 | GE3: 0.58516 | GF3: 0.58832 | GG3: 0.59148 | GH3: 0.59464 | GI3: 0.59781 | GJ3: 0.60097 | GK3: 0.60413 | GL3: 0.6073 | GM3: 0.61046 | GN3: 0.61362 | GO3: 0.61678 | GP3: 0.61995 | GQ3: 0.62311 | GR3: 0.62627 | GS3: 0.62944 | GT3: 0.6326 | GU3: 0.63576 | GV3: 0.63893 | GW3: 0.64209 | GX3: 0.64525 | GY3: 0.64842 | GZ3: 0.65158 | HA3: 0.65474 | HB3: 0.6579 | HC3: 0.66107 | HD3: 0.66423 | HE3: 0.66739 | HF3: 0.67056 | HG3: 0.67372 | HH3: 0.67688 | HI3: 0.68004 | HJ3: 0.68321 | HK3: 0.68637 | HL3: 0.68953 | HM3: 0.6927 | HN3: 0.69586 | HO3: 0.69902 | HP3: 0.70219 | HQ3: 0.70535 | HR3: 0.70851 | HS3: 0.71168 | HT3: 0.71484 | HU3: 0.718 | HV3: 0.72116 | HW3: 0.72433 | HX3: 0.72749 | HY3: 0.73065 | HZ3: 0.73382 | IA3: 0.73698 | IB3: 0.74014 | IC3: 0.7433 | ID3: 0.74647 | IE3: 0.74963 | IF3: 0.75279 | IG3: 0.75596 | IH3: 0.75912 | II3: 0.76228 | IJ3: 0.76545 | IK3: 0.76861 | IL3: 0.77177 | IM3: 0.77494 | IN3: 0.7781 | IO3: 0.78126 | IP3: 0.78442 | IQ3: 0.78759 | IR3: 0.79075 | IS3: 0.79391 | IT3: 0.79708 | IU3: 0.80024 | IV3: 0.8034 | IW3: 0.80656 | IX3: 0.80973 | IY3: 0.81289 | IZ3: 0.81605 | JA3: 0.81922 | JB3: 0.82238 | JC3: 0.82554 | JD3: 0.82871 | JE3: 0.83187 | JF3: 0.83503 | JG3: 0.83819 | JH3: 0.84136 | JI3: 0.84452 | JJ3: 0.84768 | JK3: 0.85085 | JL3: 0.85401 | JM3: 0.85717 | JN3: 0.86034 | JO3: 0.8635 | JP3: 0.86666 | JQ3: 0.86982 | JR3: 0.87299 | JS3: 0.87615 | JT3: 0.87931 | JU3: 0.88248 | JV3: 0.88564 | JW3: 0.8888 | JX3: 0.89197 | JY3: 0.89513 | JZ3: 0.89829 | KA3: 0.90145 | KB3: 0.90462 | KC3: 0.90778 | KD3: 0.91094 | KE3: 0.91411 | KF3: 0.91727 | KG3: 0.92043 | KH3: 0.9236 | KI3: 0.92676 | KJ3: 0.92992 | KK3: 0.93308 | KL3: 0.93625 | KM3: 0.93941 | KN3: 0.94257 | KO3: 0.94574 | KP3: 0.9489 | KQ3: 0.95206 | KR3: 0.95523 | KS3: 0.95839 | KT3: 0.96155 | KU3: 0.96472 | KV3: 0.96788 | KW3: 0.97104 | KX3: 0.9742 | KY3: 0.97737 | KZ3: 0.98053 | LA3: 0.98369 | LB3: 0.98686 | LC3: 0.99002 | LD3: 0.99318 | LE3: 0.99634 | LF3: 0.99951 | LG3: 1.00267 | LH3: 1.00583 | LI3: 1.009 | LJ3: 1.01216 | LK3: 1.01532 | LL3: 1.01849 | LM3: 1.02165 | LN3: 1.02481 | LO3: 1.02798 | LP3: 1.03114 | LQ3: 1.0343 | LR3: 1.03746 | LS3: 1.04063 | LT3: 1.04379 | LU3: 1.04695 | LV3: 1.05012 | LW3: 1.05328 | LX3: 1.05644 | LY3: 1.0596 | LZ3: 1.06277 | MA3: 1.06593 | MB3: 1.06909 | MC3: 1.07226 | MD3: 1.07542 | ME3: 1.07858 | MF3: 1.08175 | MG3: 1.08491 | MH3: 1.08807 | MI3: 1.09124 | MJ3: 1.0944 | MK3: 1.09756 | ML3: 1.10072 | MM3: 1.10389 | MN3: 1.10705 | MO3: 1.11021 | MP3: 1.11338 | MQ3: 1.11654 | MR3: 1.1197 | MS3: 1.12286 | MT3: 1.12603 | MU3: 1.12919 | MV3: 1.13235 | MW3: 1.13552 | MX3: 1.13868 | MY3: 1.14184 | MZ3: 1.14501 | NA3: 1.14817 | NB3: 1.15133 | NC3: 1.15449 | ND3: 1.15766 | NE3: 1.16082 | NF3: 1.16398 | NG3: 1.16715 | NH3: 1.17031 | NI3: 1.17347 | NJ3: 1.17664 | NK3: 1.1798 | NL3: 1.18296 | NM3: 1.18613 | NN3: 1.18929 | NO3: 1.19245 | NP3: 1.19561 | NQ3: 1.19878 | NR3: 1.20194 | NS3: 1.2051 | NT3: 1.20827 | NU3: 1.21143 | NV3: 1.21459 | NW3: 1.21775 | NX3: 1.22092 | NY3: 1.22408 | NZ3: 1.22724 | OA3: 1.23041 | OB3: 1.23357 | OC3: 1.23673 | OD3: 1.2399 | OE3: 1.24306 | OF3: 1.24622 | OG3: 1.24938 | OH3: 1.25255 | OI3: 1.25571 | OJ3: 1.25887 | OK3: 1.26204 | OL3: 1.2652 | OM3: 1.26836 | ON3: 1.27153 | OO3: 1.27469 | OP3: 1.27785 | OQ3: 1.28102 | OR3: 1.28418 | OS3: 1.28734 | OT3: 1.2905 | OU3: 1.29367 | OV3: 1.29683 | OW3: 1.29999 | OX3: 1.30316 | OY3: 1.30632 | OZ3: 1.30948 | PA3: 1.31264 | PB3: 1.31581 | PC3: 1.31897 | PD3: 1.32213 | PE3: 1.3253 | PF3: 1.32846 | PG3: 1.33162 | PH3: 1.33479 | PI3: 1.33795 | PJ3: 1.34111 | PK3: 1.34428 | PL3: 1.34744 | PM3: 1.3506 | PN3: 1.35376 | PO3: 1.35693 | PP3: 1.36009 | PQ3: 1.36325 | PR3: 1.36642 | PS3: 1.36958 | PT3: 1.37274 | PU3: 1.3759 | PV3: 1.37907 | PW3: 1.38223 | PX3: 1.38539 | PY3: 1.38856 | PZ3: 1.39172 | QA3: 1.39488 | QB3: 1.39805 | QC3: 1.40121 | QD3: 1.40437 | QE3: 1.40754 | QF3: 1.4107 | QG3: 1.41386 | QH3: 1.41702 | QI3: 1.42019 | QJ3: 1.42335 | QK3: 1.42651 | QL3: 1.42968 | QM3: 1.43284 | QN3: 1.436 | QO3: 1.43916 | QP3: 1.44233 | QQ3: 1.44549 | QR3: 1.44865 | QS3: 1.45182 | QT3: 1.45498 | QU3: 1.45814 | QV3: 1.46131 | QW3: 1.46447 | QX3: 1.46763 | QY3: 1.47079 | QZ3: 1.47396 | RA3: 1.47712 | RB3: 1.48028 | RC3: 1.48345 | RD3: 1.48661 | RE3: 1.48977 | RF3: 1.49294 | RG3: 1.4961 | RH3: 1.49926 | RI3: 1.50242 | RJ3: 1.50559 | RK3: 1.50875 | RL3: 1.51191 | RM3: 1.51508 | RN3: 1.51824 | RO3: 1.5214 | RP3: 1.52457 | RQ3: 1.52773 | RR3: 1.53089 | RS3: 1.53406 | RT3: 1.53722 | RU3: 1.54038 | RV3: 1.54354 | RW3: 1.54671 | RX3: 1.54987 | RY3: 1.55303 | RZ3: 1.5562 | SA3: 1.55936 | SB3: 1.56252 | SC3: 1.56568 | SD3: 1.56885 | SE3: 1.57201 | SF3: 1.57517 | SG3: 1.57834 | SH3: 1.5815 | SI3: 1.58466 | SJ3: 1.58783 | SK3: 1.59099 | SL3: 1.59415 | SM3: 1.59732 | SN3: 1.60048 | SO3: 1.60364 | SP3: 1.6068 | SQ3: 1.60997 | SR3: 1.61313 | SS3: 1.61629 | ST3: 1.61946 | SU3: 1.62262 | SV3: 1.62578 | SW3: 1.62894 | SX3: 1.63211 | SY3: 1.63527 | SZ3: 1.63843 | TA3: 1.6416 | TB3: 1.64476 | TC3: 1.64792 | TD3: 1.65109 | TE3: 1.65425 | TF3: 1.65741 | TG3: 1.66058 | TH3: 1.66374 | TI3: 1.6669 | TJ3: 1.67006 | TK3: 1.67323 | TL3: 1.67639 | TM3: 1.67955 | TN3: 1.68272 | TO3: 1.68588 | TP3: 1.68904 | TQ3: 1.6922 | TR3: 1.69537 | TS3: 1.69853 | TT3: 1.70169 | TU3: 1.70486 | TV3: 1.70802 | TW3: 1.71118 | TX3: 1.71435 | TY3: 1.71751 | TZ3: 1.72067 | UA3: 1.72383 | UB3: 1.727 | UC3: 1.73016 | UD3: 1.73332 | UE3: 1.73649 | UF3: 1.73965 | UG3: 1.74281 | UH3: 1.74598 | UI3: 1.74914 | UJ3: 1.7523 | UK3: 1.75546 | UL3: 1.75863 | UM3: 1.76179 | UN3: 1.76495 | UO3: 1.76812 | UP3: 1.77128 | UQ3: 1.77444 | UR3: 1.77761 | US3: 1.78077 | UT3: 1.78393 | UU3: 1.7871 | UV3: 1.79026 | UW3: 1.79342 | UX3: 1.79658 | UY3: 1.79975 | UZ3: 1.80291 | VA3: 1.80607 | VB3: 1.80924 | VC3: 1.8124 | VD3: 1.81556 | VE3: 1.81872 | VF3: 1.82189 | VG3: 1.82505 | VH3: 1.82821 | VI3: 1.83138 | VJ3: 1.83454 | VK3: 1.8377 | VL3: 1.84087 | VM3: 1.84403 | VN3: 1.84719 | VO3: 1.85036 | VP3: 1.85352 | VQ3: 1.85668 | VR3: 1.85984 | VS3: 1.86301 | VT3: 1.86617 | VU3: 1.86933 | VV3: 1.8725 | VW3: 1.87566 | VX3: 1.87882 | VY3: 1.88198 | VZ3: 1.88515 | WA3: 1.88831 | WB3: 1.89147 | WC3: 1.89464 | WD3: 1.8978 | WE3: 1.90096 | WF3: 1.90413 | WG3: 1.90729 | WH3: 1.91045 | WI3: 1.91361 | WJ3: 1.91678 | WK3: 1.91994 | WL3: 1.9231 | WM3: 1.92627 | WN3: 1.92943 | WO3: 1.93259 | WP3: 1.93576 | WQ3: 1.93892 | WR3: 1.94208 | WS3: 1.94524 | WT3: 1.94841 | WU3: 1.95157 | WV3: 1.95473 | WW3: 1.9579 | WX3: 1.96106 | WY3: 1.96422 | WZ3: 1.96739 | XA3: 1.97055 | XB3: 1.97371 | XC3: 1.97688 | XD3: 1.98004 | XE3: 1.9832 | XF3: 1.98636 | XG3: 1.98953 | XH3: 1.99269 | XI3: 1.99585 | XJ3: 1.99902 | XK3: 2.00218 | XL3: 2.00534 | XM3: 2.0085 | XN3: 2.01167 | XO3: 2.01483 | XP3: 2.01799 | XQ3: 2.02116 | XR3: 2.02432 | XS3: 2.02748 | XT3: 2.03065 | XU3: 2.03381 | XV3: 2.03697 | XW3: 2.04013 | XX3: 2.0433 | XY3: 2.04646 | XZ3: 2.04962 | YA3: 2.05279 | YB3: 2.05595 | YC3: 2.05911 | YD3: 2.06228 | YE3: 2.06544 | YF3: 2.0686 | YG3: 2.07176 | YH3: 2.07493 | YI3: 2.07809 | YJ3: 2.08125 | YK3: 2.08442 | YL3: 2.08758 | YM3: 2.09074 | YN3: 2.09391 | YO3: 2.09707 | YP3: 2.10023 | YQ3: 2.1034 | YR3: 2.10656 | YS3: 2.10972 | YT3: 2.11288 | YU3: 2.11605 | YV3: 2.11921 | YW3: 2.12237 | YX3: 2.12554 | YY3: 2.1287 | YZ3: 2.13186 | ZA3: 2.13503 | ZB3: 2.13819 | ZC3: 2.14135 | ZD3: 2.14451 | ZE3: 2.14768 | ZF3: 2.15084 | ZG3: 2.154 | ZH3: 2.15717 | ZI3: 2.16033 | ZJ3: 2.16349 | ZK3: 2.16666 | ZL3: 2.16982 | ZM3: 2.17298 | ZN3: 2.17614 | ZO3: 2.17931 | ZP3: 2.18247 | ZQ3: 2.18563 | ZR3: 2.1888 | ZS3: 2.19196 | ZT3: 2.19512 | ZU3: 2.19828 | ZV3: 2.20145 | ZW3: 2.20461 | ZX3: 2.20777 | ZY3: 2.21094 | ZZ3: 2.2141 | AAA3: 2.21726 | AAB3: 2.22043 | AAC3: 2.22359 | AAD3: 2.22675 | AAE3: 2.22991 | AAF3: 2.23308 | AAG3: 2.23624 | AAH3: 2.2394 | AAI3: 2.24257 | AAJ3: 2.24573 | AAK3: 2.24889 | AAL3: 2.25206 | AAM3: 2.25522 | AAN3: 2.25838 | AAO3: 2.26154 | AAP3: 2.26471 | AAQ3: 2.26787 | AAR3: 2.27103 | AAS3: 2.2742 | AAT3: 2.27736 | AAU3: 2.28052 | AAV3: 2.28369 | AAW3: 2.28685 | AAX3: 2.29001 | AAY3: 2.29318 | AAZ3: 2.29634 | ABA3: 2.2995 | ABB3: 2.30266 | ABC3: 2.30583 | ABD3: 2.30899 | ABE3: 2.31215 | ABF3: 2.31532 | ABG3: 2.31848 | ABH3: 2.32164 | ABI3: 2.3248 | ABJ3: 2.32797 | ABK3: 2.33113 | ABL3: 2.33429 | ABM3: 2.33746 | ABN3: 2.34062 | ABO3: 2.34378 | ABP3: 2.34695 | ABQ3: 2.35011 | ABR3: 2.35327 | ABS3: 2.35643 | ABT3: 2.3596 | ABU3: 2.36276 | ABV3: 2.36592 | ABW3: 2.36909 | ABX3: 2.37225 | ABY3: 2.37541 | ABZ3: 2.37858 | ACA3: 2.38174 | ACB3: 2.3849 | ACC3: 2.38806 | ACD3: 2.39123 | ACE3: 2.39439 | ACF3: 2.39755 | ACG3: 2.40072 | ACH3: 2.40388 | ACI3: 2.40704 | ACJ3: 2.41021 | ACK3: 2.41337 | ACL3: 2.41653 | ACM3: 2.4197 | ACN3: 2.42286 | ACO3: 2.42602 | ACP3: 2.42918 | ACQ3: 2.43235 | ACR3: 2.43551 | ACS3: 2.43867 | ACT3: 2.44184 | ACU3: 2.445 | ACV3: 2.44816 | ACW3: 2.45133 | ACX3: 2.45449 | ACY3: 2.45765 | ACZ3: 2.46081 | ADA3: 2.46398 | ADB3: 2.46714 | ADC3: 2.4703 | ADD3: 2.47347 | ADE3: 2.47663 | ADF3: 2.47979 | ADG3: 2.48296 | ADH3: 2.48612 | ADI3: 2.48928 | ADJ3: 2.49244 | ADK3: 2.49561 | ADL3: 2.49877 | ADM3: 2.50193 | ADN3: 2.5051 | ADO3: 2.50826 | ADP3: 2.51142 | ADQ3: 2.51458 | ADR3: 2.51775 | ADS3: 2.52091 | ADT3: 2.52407 | ADU3: 2.52724 | ADV3: 2.5304 | ADW3: 2.53356 | ADX3: 2.53673 | ADY3: 2.53989 | ADZ3: 2.54305 | AEA3: 2.54621 | AEB3: 2.54938 | AEC3: 2.55254 | AED3: 2.5557 | AEE3: 2.55887 | AEF3: 2.56203 | AEG3: 2.56519 | AEH3: 2.56836 | AEI3: 2.57152 | AEJ3: 2.57468 | AEK3: 2.57784 | AEL3: 2.58101 | AEM3: 2.58417 | AEN3: 2.58733 | AEO3: 2.5905 | AEP3: 2.59366 | AEQ3: 2.59682 | AER3: 2.59999 | AES3: 2.60315 | AET3: 2.60631 | AEU3: 2.60948 | AEV3: 2.61264 | AEW3: 2.6158 | AEX3: 2.61896 | AEY3: 2.62213 | AEZ3: 2.62529 | AFA3: 2.62845 | AFB3: 2.63162 | AFC3: 2.63478 | AFD3: 2.63794 | AFE3: 2.6411 | AFF3: 2.64427 | AFG3: 2.64743 | AFH3: 2.65059 | AFI3: 2.65376 | AFJ3: 2.65692 | AFK3: 2.66008 | AFL3: 2.66325 | AFM3: 2.66641 | AFN3: 2.66957 | AFO3: 2.67274 | AFP3: 2.6759 | AFQ3: 2.67906 | AFR3: 2.68222 | AFS3: 2.68539 | AFT3: 2.68855 | AFU3: 2.69171 | AFV3: 2.69488 | AFW3: 2.69804 | AFX3: 2.7012 | AFY3: 2.70436 | AFZ3: 2.70753 | AGA3: 2.71069 | AGB3: 2.71385 | AGC3: 2.71702 | AGD3: 2.72018 | AGE3: 2.72334 | AGF3: 2.72651 | AGG3: 2.72967 | AGH3: 2.73283 | AGI3: 2.736 | AGJ3: 2.73916 | AGK3: 2.74232 | AGL3: 2.74548 | AGM3: 2.74865 | AGN3: 2.75181 | AGO3: 2.75497 | AGP3: 2.75814 | AGQ3: 2.7613 | AGR3: 2.76446 | AGS3: 2.76762 | AGT3: 2.77079 | AGU3: 2.77395 | AGV3: 2.77711 | AGW3: 2.78028 | AGX3: 2.78344 | AGY3: 2.7866 | AGZ3: 2.78977 | AHA3: 2.79293 | AHB3: 2.79609 | AHC3: 2.79926 | AHD3: 2.80242 | AHE3: 2.80558 | AHF3: 2.80874 | AHG3: 2.81191 | AHH3: 2.81507 | AHI3: 2.81823 | AHJ3: 2.8214 | AHK3: 2.82456 | AHL3: 2.82772 | AHM3: 2.83088 | AHN3: 2.83405 | AHO3: 2.83721 | AHP3: 2.84037 | AHQ3: 2.84354
A4: 1.5 | B4: =$F$2*HS_Xray_Raw_data!B3 -> 0.51591197 | C4: =$F$2*HS_Xray_Raw_data!C3 -> 0.51484507 | D4: =$F$2*HS_Xray_Raw_data!D3 -> 0.51374626 | E4: =$F$2*HS_Xray_Raw_data!E3 -> 0.51262126 | F4: =$F$2*HS_Xray_Raw_data!F3 -> 0.51147657 | G4: =$F$2*HS_Xray_Raw_data!G3 -> 0.51031899 | H4: =$F$2*HS_Xray_Raw_data!H3 -> 0.50915476 | I4: =$F$2*HS_Xray_Raw_data!I3 -> 0.50798976 | ... AHQ4: =$F$2*HS_Xray_Raw_data!AHQ3 -> 0.0094682568
A5: 2.5 | B5: =$F$2*HS_Xray_Raw_data!B4 -> 0.52085161 | C5: =$F$2*HS_Xray_Raw_data!C4 -> 0.51997458 | D5: =$F$2*HS_Xray_Raw_data!D4 -> 0.51908155 | E5: =$F$2*HS_Xray_Raw_data!E4 -> 0.5181799 | F5: =$F$2*HS_Xray_Raw_data!F4 -> 0.51727809 | G5: =$F$2*HS_Xray_Raw_data!G4 -> 0.51638519 | H5: =$F$2*HS_Xray_Raw_data!H4 -> 0.51551013 | I5: =$F$2*HS_Xray_Raw_data!I4 -> 0.51466179 | ... AHQ5: =$F$2*HS_Xray_Raw_data!AHQ4 -> 0.0060515565
A6: 3.5 | B6: =$F$2*HS_Xray_Raw_data!B5 -> 0.52390129 | C6: =$F$2*HS_Xray_Raw_data!C5 -> 0.52313989 | D6: =$F$2*HS_Xray_Raw_data!D5 -> 0.52236683 | E6: =$F$2*HS_Xray_Raw_data!E5 -> 0.52158812 | F6: =$F$2*HS_Xray_Raw_data!F5 -> 0.52081084 | G6: =$F$2*HS_Xray_Raw_data!G5 -> 0.52004271 | H6: =$F$2*HS_Xray_Raw_data!H5 -> 0.51929125 | I6: =$F$2*HS_Xray_Raw_data!I5 -> 0.51856422 | ... AHQ6: =$F$2*HS_Xray_Raw_data!AHQ5 -> 0.001794953
A7: 5 | B7: =$F$2*HS_Xray_Raw_data!B6 -> 0.52530944 | C7: =$F$2*HS_Xray_Raw_data!C6 -> 0.52462502 | D7: =$F$2*HS_Xray_Raw_data!D6 -> 0.52394064 | E7: =$F$2*HS_Xray_Raw_data!E6 -> 0.52326492 | F7: =$F$2*HS_Xray_Raw_data!F6 -> 0.52260653 | G7: =$F$2*HS_Xray_Raw_data!G6 -> 0.52197376 | H7: =$F$2*HS_Xray_Raw_data!H6 -> 0.52137373 | I7: =$F$2*HS_Xray_Raw_data!I6 -> 0.52081263 | ... AHQ7: =$F$2*HS_Xray_Raw_data!AHQ6 -> 0.0054382359
A8: 7.167 | B8: =$F$2*HS_Xray_Raw_data!B7 -> 0.52754329 | C8: =$F$2*HS_Xray_Raw_data!C7 -> 0.52684991 | D8: =$F$2*HS_Xray_Raw_data!D7 -> 0.52613832 | E8: =$F$2*HS_Xray_Raw_data!E7 -> 0.52541956 | F8: =$F$2*HS_Xray_Raw_data!F7 -> 0.52470599 | G8: =$F$2*HS_Xray_Raw_data!G7 -> 0.52401022 | H8: =$F$2*HS_Xray_Raw_data!H7 -> 0.52334395 | I8: =$F$2*HS_Xray_Raw_data!I7 -> 0.52271769 | ... AHQ8: =$F$2*HS_Xray_Raw_data!AHQ7 -> 0.0069550563
A9: 8 | B9: =$F$2*HS_Xray_Raw_data!B8 -> 0.52683981 | C9: =$F$2*HS_Xray_Raw_data!C8 -> 0.52626059 | D9: =$F$2*HS_Xray_Raw_data!D8 -> 0.52566366 | E9: =$F$2*HS_Xray_Raw_data!E8 -> 0.52505649 | F9: =$F$2*HS_Xray_Raw_data!F8 -> 0.52444786 | G9: =$F$2*HS_Xray_Raw_data!G8 -> 0.52384727 | H9: =$F$2*HS_Xray_Raw_data!H8 -> 0.52326371 | I9: =$F$2*HS_Xray_Raw_data!I8 -> 0.52270579 | ... AHQ9: =$F$2*HS_Xray_Raw_data!AHQ8 -> 0.0067382842
A10: 9 | B10: =$F$2*HS_Xray_Raw_data!B9 -> 0.52711168 | C10: =$F$2*HS_Xray_Raw_data!C9 -> 0.5265002 | D10: =$F$2*HS_Xray_Raw_data!D9 -> 0.52589781 | E10: =$F$2*HS_Xray_Raw_data!E9 -> 0.5253107 | F10: =$F$2*HS_Xray_Raw_data!F9 -> 0.52474557 | G10: =$F$2*HS_Xray_Raw_data!G9 -> 0.52420938 | H10: =$F$2*HS_Xray_Raw_data!H9 -> 0.52370816 | I10: =$F$2*HS_Xray_Raw_data!I9 -> 0.52324764 | ... AHQ10: =$F$2*HS_Xray_Raw_data!AHQ9 -> 0.0075820174
A11: 10 | B11: =$F$2*HS_Xray_Raw_data!B10 -> 0.5274447 | C11: =$F$2*HS_Xray_Raw_data!C10 -> 0.52681328 | D11: =$F$2*HS_Xray_Raw_data!D10 -> 0.52617208 | E11: =$F$2*HS_Xray_Raw_data!E10 -> 0.52552954 | F11: =$F$2*HS_Xray_Raw_data!F10 -> 0.52489501 | G11: =$F$2*HS_Xray_Raw_data!G10 -> 0.52427836 | H11: =$F$2*HS_Xray_Raw_data!H10 -> 0.52368869 | I11: =$F$2*HS_Xray_Raw_data!I10 -> 0.52313471 | ... AHQ11: =$F$2*HS_Xray_Raw_data!AHQ10 -> 0.0077929832
A12: 11 | B12: =$F$2*HS_Xray_Raw_data!B11 -> 0.5261316 | C12: =$F$2*HS_Xray_Raw_data!C11 -> 0.52559903 | D12: =$F$2*HS_Xray_Raw_data!D11 -> 0.52506515 | E12: =$F$2*HS_Xray_Raw_data!E11 -> 0.52453371 | F12: =$F$2*HS_Xray_Raw_data!F11 -> 0.52400926 | G12: =$F$2*HS_Xray_Raw_data!G11 -> 0.52349715 | H12: =$F$2*HS_Xray_Raw_data!H11 -> 0.52300235 | I12: =$F$2*HS_Xray_Raw_data!I11 -> 0.52253013 | ... AHQ12: =$F$2*HS_Xray_Raw_data!AHQ11 -> 0.0036694521
A13: 12 | B13: =$F$2*HS_Xray_Raw_data!B12 -> 0.52690429 | C13: =$F$2*HS_Xray_Raw_data!C12 -> 0.52620694 | D13: =$F$2*HS_Xray_Raw_data!D12 -> 0.52550059 | E13: =$F$2*HS_Xray_Raw_data!E12 -> 0.52479651 | F13: =$F$2*HS_Xray_Raw_data!F12 -> 0.52410671 | G13: =$F$2*HS_Xray_Raw_data!G12 -> 0.52344367 | H13: =$F$2*HS_Xray_Raw_data!H12 -> 0.52281872 | I13: =$F$2*HS_Xray_Raw_data!I12 -> 0.52224248 | ... AHQ13: =$F$2*HS_Xray_Raw_data!AHQ12 -> 0.0053060576
A14: 13.5 | B14: =$F$2*HS_Xray_Raw_data!B13 -> 0.5250197 | C14: =$F$2*HS_Xray_Raw_data!C13 -> 0.52434695 | D14: =$F$2*HS_Xray_Raw_data!D13 -> 0.52367179 | E14: =$F$2*HS_Xray_Raw_data!E13 -> 0.52300685 | F14: =$F$2*HS_Xray_Raw_data!F13 -> 0.52236546 | G14: =$F$2*HS_Xray_Raw_data!G13 -> 0.5217608 | H14: =$F$2*HS_Xray_Raw_data!H13 -> 0.52120467 | I14: =$F$2*HS_Xray_Raw_data!I13 -> 0.5207073 | ... AHQ14: =$F$2*HS_Xray_Raw_data!AHQ13 -> 0.0065547525
A15: 15 | B15: =$F$2*HS_Xray_Raw_data!B14 -> 0.5255134 | C15: =$F$2*HS_Xray_Raw_data!C14 -> 0.52503673 | D15: =$F$2*HS_Xray_Raw_data!D14 -> 0.52456408 | E15: =$F$2*HS_Xray_Raw_data!E14 -> 0.52410318 | F15: =$F$2*HS_Xray_Raw_data!F14 -> 0.52366214 | G15: =$F$2*HS_Xray_Raw_data!G14 -> 0.52324876 | H15: =$F$2*HS_Xray_Raw_data!H14 -> 0.52286956 | I15: =$F$2*HS_Xray_Raw_data!I14 -> 0.52252996 | ... AHQ15: =$F$2*HS_Xray_Raw_data!AHQ14 -> 0.0048499405
... A28: 60 | B28: =$F$2*HS_Xray_Raw_data!B27 -> 0.526179 | C28: =$F$2*HS_Xray_Raw_data!C27 -> 0.52546917 | D28: =$F$2*HS_Xray_Raw_data!D27 -> 0.52478798 | E28: =$F$2*HS_Xray_Raw_data!E27 -> 0.52414884 | F28: =$F$2*HS_Xray_Raw_data!F27 -> 0.52356511 | G28: =$F$2*HS_Xray_Raw_data!G27 -> 0.52304894 | H28: =$F$2*HS_Xray_Raw_data!H27 -> 0.52261026 | I28: =$F$2*HS_Xray_Raw_data!I27 -> 0.52225635 | ... AHQ28: =$F$2*HS_Xray_Raw_data!AHQ27 -> 0.29506018
A30: Avg (5min and beyond) | B30: =AVERAGE(B7:B28) -> 0.52596153

Sheet HS_Xray_Raw_data
A1: Smoothed Average Attenuation Profiles from X-ray radiographs
